Workbook

Sheet Planung
A1: Planung | AW1: HINWEIS: Rote Markierung Rennname+Datum = zeitliche Überschneidung/Ausschluss-Konflikt. Rote X-Felder = dieser Fahrer ist an der Überschneidung beteiligt ODER Kader über Maximum. Grüne X-Felder = Kader hat Maximum erreicht. Großes und kleines X haben dieselbe Bedeutung. Zeile 6: grün = Max erreicht, rot = überschritten. Renntage (Spalte B): helleres Rot ab 71 Tagen (über Maximum 70 laut Regelwerk).
C2: CWT | D2: 2.Pro | E2: CWT | F2: 2.Pro | G2: 2.Pro | H2: CWT | I2: CWT | J2: CWT | K2: CWT | L2: CWT | M2: CWT | N2: CWT | O2: CWT | P2: CWT | Q2: CWT | R2: CWT | S2: CWT | T2: CWT | U2: CWT | V2: CWT | W2: 2.Pro | X2: CWT | Y2: CWT | Z2: CWT | AA2: CWT | AB2: CWT | AC2: 2.Pro | AD2: CWT | AE2: CWT | AG2: CWT | AH2: CWT | AI2: CWT | AJ2: 2.Pro | AK2: CWT | AL2: 2.Pro | AM2: CWT | AN2: CWT | AO2: CWT | AP2: CWT | AQ2: CWT | AT2: CWT | AU2: CWT
C3: Tour Down Under | D3: Tour of Oman | E3: UAE Tour | F3: Volta ao Algarve | G3: Vuelta a Andalucia | H3: Omloop Nieuwsblad | I3: Kuurne-Brussel-Kuurne | J3: Strade Bianche | K3: Paris-Nice | L3: Tirreno-Adriatico | M3: Milano-Sanremo | N3: Volta a Catalunya | O3: Ronde van Brugge | P3: E3 Classic | Q3: Gent-Wevelgem | R3: Dwars door Vlaanderen | S3: Ronde van Vlaanderen | T3: Izulia Basque Country | U3: Paris-Roubaix | V3: Amstel Gold Race | W3: Tour of the Alpes | X3: La Fleche Wallonne | Y3: Liege-Bastogne-Liege | Z3: Tour de Romandie | AA3: Eschborn-Frankfurt | AB3: Giro d'Italia | AC3: Tour de Slovenia | AD3: Criterium de Dauphine | AE3: Tour de Suisse | AF3: National Championchips | AG3: Tour de France | AH3: San Sebastian | AI3: Tour de Pologne | AJ3: Tour de Denmark | AK3: ADAC Cyclassis Hamburg | AL3: LIDL Deutschland Tour | AM3: Renewl Tour | AN3: Vuelta a Espana | AO3: Bretagne Classic | AP3: GP Quebec | AQ3: GP Montreal | AR3: World Championships | AS3: European Championships | AT3: Il Lombardia | AU3: Tour de Changxi
B4: Datum | C4: 20.-25.01. | D4: 07.-11.02. | E4: 16.-22.02. | F4: 18.-22.02. | G4: 18.-22.02. | H4: 28.02. | I4: 01.03. | J4: 07.03. | K4: 08.-15.03. | L4: 09.-15.03. | M4: 21.03. | N4: 23.-29.03. | O4: 26.03. | P4: 27.03. | Q4: 29.03. | R4: 01.04. | S4: 05.04. | T4: 06.-11.04. | U4: 12.04. | V4: 19.04. | W4: 20.-24.04. | X4: 22.04. | Y4: 26.04. | Z4: 28.04.-03.05. | AA4: 01.05. | AB4: 08.-31.05. | AC4: 04.-08.06. | AD4: 07.-14.06. | AE4: 17.-21.06. | AF4: 26.-29.06. | AG4: 04.-26.07. | AH4: 01.08. | AI4: 03.- 09.08 | AJ4: 11.-15.08. | AK4: 16.08. | AL4: 19.-23.08. | AM4: 19.-23.08. | AN4: 22.08.-13.09. | AO4: 30.08. | AP4: 11.09. | AQ4: 13.09. | AR4: 20.-27.09. | AS4: 02.-07.10. | AT4: 10.10. | AU4: 13.-18.10.
B5: Etapppen | C5: 6 | D5: 5 | E5: 7 | F5: 5 | G5: 5 | H5: 1 | I5: 1 | J5: 1 | K5: 8 | L5: 7 | M5: 1 | N5: 7 | O5: 1 | P5: 1 | Q5: 1 | R5: 1 | S5: 1 | T5: 5 | U5: 1 | V5: 1 | W5: 5 | X5: 1 | Y5: 1 | Z5: 6 | AA5: 1 | AB5: 21 | AC5: 5 | AD5: 8 | AE5: 5 | AF5: 1 | AG5: 21 | AH5: 1 | AI5: 7 | AJ5: 5 | AK5: 1 | AL5: 5 | AM5: 5 | AN5: 21 | AO5: 1 | AP5: 1 | AQ5: 1 | AR5: 1 | AS5: 1 | AT5: 1 | AU5: 5
A6: Fahrer | B6: Renntage | C6: =7&"/"&COUNTIF(C7:C36,"X") | D6: =7&"/"&COUNTIF(D7:D36,"X") | E6: =7&"/"&COUNTIF(E7:E36,"X") | F6: =8&"/"&COUNTIF(F7:F36,"X") | G6: =7&"/"&COUNTIF(G7:G36,"X") | H6: =7&"/"&COUNTIF(H7:H36,"X") | I6: =7&"/"&COUNTIF(I7:I36,"X") | J6: =7&"/"&COUNTIF(J7:J36,"X") | K6: =8&"/"&COUNTIF(K7:K36,"X") | L6: =7&"/"&COUNTIF(L7:L36,"X") | M6: =7&"/"&COUNTIF(M7:M36,"X") | N6: =7&"/"&COUNTIF(N7:N36,"X") | O6: =6&"/"&COUNTIF(O7:O36,"X") | P6: =7&"/"&COUNTIF(P7:P36,"X") | Q6: =8&"/"&COUNTIF(Q7:Q36,"X") | R6: =7&"/"&COUNTIF(R7:R36,"X") | S6: =7&"/"&COUNTIF(S7:S36,"X") | T6: =7&"/"&COUNTIF(T7:T36,"X") | U6: =7&"/"&COUNTIF(U7:U36,"X") | V6: =7&"/"&COUNTIF(V7:V36,"X") | W6: =7&"/"&COUNTIF(W7:W36,"X") | X6: =7&"/"&COUNTIF(X7:X36,"X") | Y6: =7&"/"&COUNTIF(Y7:Y36,"X") | ... AA6: =7&"/"&COUNTIF(AA7:AA36,"X") | AB6: =8&"/"&COUNTIF(AB7:AB36,"X") | AC6: =7&"/"&COUNTIF(AC7:AC36,"X") | AD6: =7&"/"&COUNTIF(AD7:AD36,"X") | AE6: =7&"/"&COUNTIF(AE7:AE36,"X") | AF6: =7&"/"&COUNTIF(AF7:AF36,"X") | AG6: =8&"/"&COUNTIF(AG7:AG36,"X") | AH6: =7&"/"&COUNTIF(AH7:AH36,"X") | AI6: =7&"/"&COUNTIF(AI7:AI36,"X") | AJ6: =7&"/"&COUNTIF(AJ7:AJ36,"X") | AK6: =7&"/"&COUNTIF(AK7:AK36,"X") | AL6: =6&"/"&COUNTIF(AL7:AL36,"X") | AM6: =7&"/"&COUNTIF(AM7:AM36,"X") | AN6: =8&"/"&COUNTIF(AN7:AN36,"X") | AO6: =7&"/"&COUNTIF(AO7:AO36,"X") | AP6: =7&"/"&COUNTIF(AP7:AP36,"X") | AQ6: =7&"/"&COUNTIF(AQ7:AQ36,"X") | AR6: =7&"/"&COUNTIF(AR7:AR36,"X") | AS6: =7&"/"&COUNTIF(AS7:AS36,"X") | AT6: =7&"/"&COUNTIF(AT7:AT36,"X") | AU6: =7&"/"&COUNTIF(AU7:AU36,"X")
A7: =IF(Fahrerwerte!A4="","",Fahrerwerte!A4) | B7: =SUMPRODUCT(($C7:$AT7="X")*($C$5:$AT$5)) | E7: X | H7: X | J7: X | K7: X | M7: X | P7: X | S7: X | V7: X | X7: X | Y7: X | AD7: X | AF7: X | AG7: X | AP7: X | AQ7: X | AR7: X | AS7: X | AT7: X
A8: =IF(Fahrerwerte!A5="","",Fahrerwerte!A5) | B8: =SUMPRODUCT(($C8:$AT8="X")*($C$5:$AT$5)) | L8: X | Z8: X | AB8: X | AH8: X | AK8: X | AN8: X
A9: =IF(Fahrerwerte!A6="","",Fahrerwerte!A6) | B9: =SUMPRODUCT(($C9:$AT9="X")*($C$5:$AT$5)) | G9: X | Z9: X | AB9: X | AE9: X | AG9: X | AT9: X
A10: =IF(Fahrerwerte!A7="","",Fahrerwerte!A7) | B10: =SUMPRODUCT(($C10:$AT10="X")*($C$5:$AT$5)) | K10: X | N10: X | T10: X | AB10: X | AE10: X | AG10: X | AT10: X
A11: =IF(Fahrerwerte!A8="","",Fahrerwerte!A8) | B11: =SUMPRODUCT(($C11:$AT11="X")*($C$5:$AT$5)) | F11: X | J11: X | N11: X | T11: X | X11: X | Y11: X | Z11: X | AB11: X | AG11: X
A12: =IF(Fahrerwerte!A9="","",Fahrerwerte!A9) | B12: =SUMPRODUCT(($C12:$AT12="X")*($C$5:$AT$5)) | L12: X | W12: X | Z12: X | AB12: X | AH12: X | AI12: X | AN12: X
A13: =IF(Fahrerwerte!A10="","",Fahrerwerte!A10) | B13: =SUMPRODUCT(($C13:$AT13="X")*($C$5:$AT$5)) | J13: X | L13: X | Z13: X | AB13: X | AF13: X | AH13: X | AI13: X | AK13: X | AN13: X | AS13: X
A14: =IF(Fahrerwerte!A11="","",Fahrerwerte!A11) | B14: =SUMPRODUCT(($C14:$AT14="X")*($C$5:$AT$5)) | J14: X | K14: X | T14: X | V14: X | X14: X | Y14: X | AD14: X | AG14: X | AN14: X | AT14: X
A15: =IF(Fahrerwerte!A12="","",Fahrerwerte!A12) | B15: =SUMPRODUCT(($C15:$AT15="X")*($C$5:$AT$5)) | G15: X | J15: X | L15: X | N15: X | T15: X | V15: X | X15: X | Y15: X | AC15: X | AF15: X | AH15: X | AI15: X | AK15: X | AN15: X | AR15: X | AS15: X | AT15: X
A16: =IF(Fahrerwerte!A13="","",Fahrerwerte!A13) | B16: =SUMPRODUCT(($C16:$AT16="X")*($C$5:$AT$5)) | L16: X | V16: X | X16: X | Y16: X | Z16: X | AB16: X | AE16: X | AF16: X | AG16: X | AP16: X | AQ16: X | AR16: X | AT16: X
A17: =IF(Fahrerwerte!A14="","",Fahrerwerte!A14) | B17: =SUMPRODUCT(($C17:$AT17="X")*($C$5:$AT$5)) | J17: X | L17: X | N17: X | V17: X | X17: X | Y17: X | AD17: X | AG17: X | AN17: X
A18: =IF(Fahrerwerte!A15="","",Fahrerwerte!A15) | B18: =SUMPRODUCT(($C18:$AT18="X")*($C$5:$AT$5)) | C18: X | G18: X | H18: X | I18: X | K18: X | M18: X | O18: X | P18: X | Q18: X | R18: X | S18: X | AC18: X | AF18: X | AH18: X | AI18: X | AK18: X | AL18: X | AP18: X | AQ18: X | AR18: X | AS18: X | AU18: X
A19: =IF(Fahrerwerte!A16="","",Fahrerwerte!A16) | B19: =SUMPRODUCT(($C19:$AT19="X")*($C$5:$AT$5)) | E19: X | H19: X | I19: X | J19: X | L19: X | M19: X | O19: X | P19: X | Q19: X | R19: X | S19: X | Z19: X | AC19: X | AF19: X | AH19: X | AI19: X | AK19: X | AL19: X | AO19: X | AP19: X | AQ19: X | AR19: X | AS19: X | AU19: X
A20: =IF(Fahrerwerte!A17="","",Fahrerwerte!A17) | B20: =SUMPRODUCT(($C20:$AT20="X")*($C$5:$AT$5)) | E20: X | H20: X | I20: X | M20: X | O20: X | P20: X | Q20: X | R20: X | S20: X | U20: X | AC20: X | AJ20: X | AM20: X | AO20: X | AP20: X | AQ20: X | AS20: X | AU20: X
A21: =IF(Fahrerwerte!A18="","",Fahrerwerte!A18) | B21: =SUMPRODUCT(($C21:$AT21="X")*($C$5:$AT$5)) | C21: X | E21: X | H21: X | I21: X | K21: X | M21: X | O21: X | P21: X | Q21: X | R21: X | S21: X | U21: X | AD21: X | AJ21: X | AO21: X | AP21: X
A22: =IF(Fahrerwerte!A19="","",Fahrerwerte!A19) | B22: =SUMPRODUCT(($C22:$AT22="X")*($C$5:$AT$5)) | E22: X | H22: X | I22: X | O22: X | P22: X | Q22: X | R22: X | S22: X | U22: X | AC22: X | AI22: X | AJ22: X | AN22: X | AU22: X
A23: =IF(Fahrerwerte!A20="","",Fahrerwerte!A20) | B23: =SUMPRODUCT(($C23:$AT23="X")*($C$5:$AT$5)) | C23: X | E23: X | H23: X | I23: X | M23: X | P23: X | Q23: X | R23: X | S23: X | U23: X | AB23: X | AE23: X | AF23: X | AJ23: X | AO23: X | AP23: X | AQ23: X | AR23: X | AS23: X
A24: =IF(Fahrerwerte!A21="","",Fahrerwerte!A21) | B24: =SUMPRODUCT(($C24:$AT24="X")*($C$5:$AT$5)) | E24: X | I24: X | M24: X | Q24: X | R24: X | U24: X | AC24: X | AE24: X | AG24: X | AJ24: X | AM24: X | AO24: X | AQ24: X | AR24: X
A25: =IF(Fahrerwerte!A22="","",Fahrerwerte!A22) | B25: =SUMPRODUCT(($C25:$AT25="X")*($C$5:$AT$5)) | C25: X | D25: X | F25: X | U25: X | AA25: X | AJ25: X | AM25: X | AO25: X | AU25: X
A26: =IF(Fahrerwerte!A23="","",Fahrerwerte!A23) | B26: =SUMPRODUCT(($C26:$AT26="X")*($C$5:$AT$5)) | C26: X | F26: X | T26: X | AA26: X | AC26: X | AJ26: X | AM26: X | AO26: X | AU26: X
A27: =IF(Fahrerwerte!A24="","",Fahrerwerte!A24) | B27: =SUMPRODUCT(($C27:$AT27="X")*($C$5:$AT$5)) | G27: X | K27: X | Q27: X | AE27: X | AK27: X | AM27: X
A28: =IF(Fahrerwerte!A25="","",Fahrerwerte!A25) | B28: =SUMPRODUCT(($C28:$AT28="X")*($C$5:$AT$5)) | G28: X | T28: X | V28: X | W28: X | Y28: X | AE28: X | AH28: X | AK28: X | AN28: X | AT28: X | AU28: X
A29: =IF(Fahrerwerte!A26="","",Fahrerwerte!A26) | B29: =SUMPRODUCT(($C29:$AT29="X")*($C$5:$AT$5)) | D29: X | F29: X | K29: X | V29: X | X29: X | AD29: X
A30: =IF(Fahrerwerte!A27="","",Fahrerwerte!A27) | B30: =SUMPRODUCT(($C30:$AT30="X")*($C$5:$AT$5)) | C30: X | D30: X | F30: X | N30: X | W30: X | AI30: X | AL30: X
A31: =IF(Fahrerwerte!A28="","",Fahrerwerte!A28) | B31: =SUMPRODUCT(($C31:$AT31="X")*($C$5:$AT$5)) | D31: X | F31: X | T31: X | W31: X | AA31: X | AL31: X
A32: =IF(Fahrerwerte!A29="","",Fahrerwerte!A29) | B32: =SUMPRODUCT(($C32:$AT32="X")*($C$5:$AT$5)) | D32: X | F32: X | W32: X | AA32: X | AM32: X
A33: =IF(Fahrerwerte!A30="","",Fahrerwerte!A30) | B33: =SUMPRODUCT(($C33:$AT33="X")*($C$5:$AT$5)) | D33: X | F33: X | N33: X | W33: X | AA33: X | AL33: X
A34: =IF(Fahrerwerte!A31="","",Fahrerwerte!A31) | B34: =SUMPRODUCT(($C34:$AT34="X")*($C$5:$AT$5)) | G34: X | K34: X | N34: X | AD34: X | AM34: X
A35: =IF(Fahrerwerte!A32="","",Fahrerwerte!A32) | B35: =SUMPRODUCT(($C35:$AT35="X")*($C$5:$AT$5)) | W35: X | AA35: X | AD35: X | AL35: X
A36: =IF(Fahrerwerte!A33="","",Fahrerwerte!A33) | B36: =SUMPRODUCT(($C36:$AT36="X")*($C$5:$AT$5)) | C36: X | D36: X | G36: X | O36: X | U36: X | AA36: X
B71: =IF(Planung!B72="","",Planung!B72)
D72: =IF(Planung!D73="","",Planung!D73)
B266: * Frühjahrs-Klassiker-Blöcke (Formanstieg): Wenn mehrere Eintagesrennen in engem Abstand aufeinanderfolgen (wenige Tage, z. B. E3 → Gent-Wevelgem → Dwars → Flandern → Roubaix, oder Amstel → Flèche → LBL), ist es der Normalfall und gewollt, dass dieselben Fahrer (Klassiker-Kapitäne, passende Sprinter/Edelhelfer) mehrere dieser Rennen bestreiten – nicht nur eines oder zwei. Das dient dem Form- und Fitnessanstieg. Die KI soll Klassiker-Spezialisten in solchen Blöcken bewusst mehrfach einsetzen, sofern keine harten Datumsüberschneidungen und die Kadergröße je Rennen es zulassen. Einzelne isolierte Starts ohne Block-Logik sind für Klassiker-Kapitäne die Ausnahme.
B378: 2) Zeitliche Überschneidungen und Ausschluss-Paare: Für JEDEN Fahrer alle gesetzten Rennen paarweise auf Datumsüberschneidung prüfen (inkl. Eintagesrennen in einer Rundfahrt, Parallelrennen wie Paris–Nice/Tirreno, UAE/Algarve/Andalucía, Catalunya/Flandern-Woche, Deutschland Tour/Renewi/Vuelta-Start, Alpes/Flèche). Zusätzlich Ausschluss-Paare ohne Kalenderüberlappung, aber mit zu engem Abstand / gleicher Funktion: Critérium du Dauphiné und Tour de Suisse (Tour-Vorbereitung – pro Fahrer nur eines). Jeder Treffer ist ein Fehler und muss vor Abschluss beseitigt werden. Keine Fehlermarkierung bei rein aufeinanderfolgenden Tagen ohne Überlappung (z. B. Amstel 19.04. und Tour of the Alps ab 20.04.).
...

Sheet Fahrerwerte
A1: Fahrerwerte
A3: Name | B3: EB | C3: BE | D3: MG | E3: HÜG | F3: ZF | G3: PRL | H3: KSP | I3: SP | J3: BES | K3: ABF | L3: ASR | M3: AUS | N3: ZÄH | O3: REG | P3: Fahrerrolle | Q3: Bevorzugte Rennen
A4: Remco Evenepoel | B4: 85 | C4: 81 | D4: 84 | E4: 84 | F4: 85 | G4: 84 | H4: 73 | I4: 71 | J4: 77 | K4: 75 | L4: 85 | M4: 83 | N4: 83 | O4: 81 | P4: Kapitän | Q4: Zeitfahren
A5: Primož Roglic | B5: 78 | C5: 81 | D5: 82 | E5: 81 | F5: 79 | G5: 81 | H5: 68 | I5: 68 | J5: 78 | K5: 80 | L5: 70 | M5: 82 | N5: 81 | O5: 83 | P5: Kapitän | Q5: Bergankünfte
A6: Florian Lipowitz | B6: 75 | C6: 82 | D6: 81 | E6: 75 | F6: 75 | G6: 79 | H6: 66 | I6: 65 | J6: 74 | K6: 75 | L6: 75 | M6: 82 | N6: 81 | O6: 81 | P6: Kapitän | Q6: Bergankünfte
A7: Aleksandr Vlasov | B7: 76 | C7: 81 | D7: 80 | E7: 78 | F7: 74 | G7: 78 | H7: 68 | I7: 65 | J7: 75 | K7: 74 | L7: 75 | M7: 80 | N7: 79 | O7: 80 | P7: Edelhelfer | Q7: Bergankünfte
A8: Daniel Felipe Martínez | B8: 75 | C8: 81 | D8: 80 | E8: 80 | F8: 73 | G8: 72 | H8: 65 | I8: 62 | J8: 77 | K8: 76 | L8: 75 | M8: 81 | N8: 78 | O8: 79 | P8: Edelhelfer | Q8: Bergankünfte
A9: Jai Hindley | B9: 73 | C9: 82 | D9: 80 | E9: 78 | F9: 68 | G9: 70 | H9: 67 | I9: 61 | J9: 77 | K9: 77 | L9: 75 | M9: 81 | N9: 79 | O9: 82 | P9: Edelhelfer | Q9: Bergankünfte
A10: Giulio Pellizzari | B10: 73 | C10: 81 | D10: 81 | E10: 76 | F10: 66 | G10: 71 | H10: 68 | I10: 64 | J10: 76 | K10: 77 | L10: 75 | M10: 80 | N10: 81 | O10: 80 | P10: Edelhelfer | Q10: Bergankünfte
A11: Maxim Van Gils | B11: 74 | C11: 76 | D11: 79 | E11: 82 | F11: 65 | G11: 73 | H11: 69 | I11: 67 | J11: 79 | K11: 75 | L11: 75 | M11: 78 | N11: 79 | O11: 76 | P11: Edelhelfer | Q11: Hügel-/Ardennen-Klassiker
A12: Jan Tratnik | B12: 81 | C12: 74 | D12: 75 | E12: 76 | F12: 74 | G12: 77 | H12: 73 | I12: 66 | J12: 74 | K12: 74 | L12: 75 | M12: 79 | N12: 72 | O12: 76 | P12: Edelhelfer | Q12: Hügel-/Ardennen-Klassiker
A13: Mattia Cattaneo | B13: 78 | C13: 78 | D13: 78 | E13: 76 | F13: 78 | G13: 77 | H13: 67 | I13: 65 | J13: 73 | K13: 75 | L13: 70 | M13: 78 | N13: 73 | O13: 78 | P13: Edelhelfer | Q13: Bergankünfte
A14: Finn Fisher-Black | B14: 77 | C14: 76 | D14: 78 | E14: 77 | F14: 74 | G14: 77 | H14: 70 | I14: 67 | J14: 74 | K14: 70 | L14: 75 | M14: 77 | N14: 76 | O14: 76 | P14: Edelhelfer | Q14: Hügel-/Ardennen-Klassiker
A15: Gianni Vermeersch | B15: 80 | C15: 68 | D15: 71 | E15: 77 | F15: 61 | G15: 72 | H15: 81 | I15: 76 | J15: 77 | K15: 78 | L15: 75 | M15: 78 | N15: 77 | O15: 73 | P15: Klassiker-Kapitän | Q15: Kopfsteinpflaster-Klassiker
... A33: Jarrad Drizners | B33: 77 | C33: 63 | D33: 64 | E33: 69 | F33: 65 | G33: 67 | H33: 73 | I33: 72 | J33: 66 | K33: 68 | L33: 60 | M33: 75 | N33: 67 | O33: 72 | P33: Wasserträger | Q33: Kopfsteinpflaster-Klassiker

Sheet Rennprofil
A1: Rennen | C1: Priorität | D1: Datum | E1: Kategorie | F1: Profil | G1: Profil-Ampel | H1: Etappen | J1: Gesamthärte | K1: Bergankunft | L1: Sprintankunft | M1: Anzahl Bergetappen | N1: Anzahl Mittelgebirgstappen | O1: Anzahl Flachetappen | P1: Kopfsteinpflaster | Q1: Höhenmeter | R1: Bergfaktor | S1: Sprintfaktor | T1: Hügelfaktor | U1: TT-Faktor | V1: Windanfälligkeit | W1: Empfohlene Fahrertypen | X1: Teilgenommene Fahrer letztes Jahr (2025)
A2: Tour Down Under | C2: C | D2: 20.01.-25.01.2026 | E2: WorldTour | F2: flach/hügelig | G2: 🔴 🟡 🟢 | H2: 6 | J2: 5 | K2: 1 | L2: 3 | M2: 1 | N2: 2 | O2: 3 | P2: Nein | Q2: ~7000 | R2: 4 | S2: 8 | T2: 4 | U2: 1 | V2: Mittel | W2: Sprinter, Helfer, Aureißer | X2: Hindley, Pithie, Tuckwell
A3: Tour of Oman | C3: D | D3: 07.02.-11.02.2026 | E3: 2.Pro | F3: hügelig | G3: 🔴 🟡 🟢 | H3: 5 | J3: 5 | K3: 1 | L3: 2 | M3: 1 | N3: 2 | O3: 2 | P3: Nein | Q3: ~7500 | R3: 5 | S3: 6 | T3: 5 | U3: 2 | V3: Mittel | W3: Sprinter, Helfer
A4: UAE Tour | C4: B | D4: 16.02.-22.02.2026 | E4: WorldTour | F4: flach+1 Berg | G4: 🔴 🟡 🟢 | H4: 7 | J4: 6 | K4: 1 | L4: 4 | M4: 1 | N4: 2 | O4: 4 | P4: Nein | Q4: ~8000 | R4: 5 | S4: 8 | T4: 3 | U4: 4 | V4: Mittel | W4: Sprinter, Kapitän oder Co-Leader, KlassikerKapitän | X4: Pellizzari, Fisher-Black, van Poppel
A5: Volta ao Algarve | C5: D | D5: 18.02.-22.02.2026 | E5: 2.Pro | F5: hügelig | G5: 🔴 🟡 🟢 | H5: 5 | J5: 6 | K5: 1 | L5: 2 | M5: 2 | N5: 1 | O5: 2 | P5: Nein | Q5: ~8500 | R5: 6 | S5: 5 | T5: 6 | U5: 3 | V5: Mittel | W5: cCo-Leader, Sprinter, Helfer | X5: Roglic, Tratnik, Meeus, Wandahl
A6: Vuelta a Andalucia | C6: D | D6: 18.02.-22.02.2026 | E6: 2.Pro | F6: hügelig | G6: 🔴 🟡 🟢 | H6: 5 | J6: 6 | K6: 1 | L6: 2 | M6: 2 | N6: 1 | O6: 2 | P6: Nein | Q6: ~8500 | R6: 6 | S6: 5 | T6: 6 | U6: 3 | V6: Mittel | W6: GC-Leader, Sprinter, Helfer
A7: Omloop | C7: B | D7: 28.02.2026 | E7: Klassiker | F7: Pflaster | G7: 🟢 | H7: 1 | J7: 6 | K7: 0 | L7: 1 | M7: 0 | N7: 0 | O7: 1 | P7: Ja | Q7: ~1200 | R7: 5 | S7: 6 | T7: 5 | U7: 1 | V7: Hoch | W7: Klassiker-Kapitän, Edelhelfer, Sprinter | X7: Tratnik, Meeus, van Dijke
A8: Kuurne-Brussel-Kuurne | C8: B | D8: 01.03.2026 | E8: Klassiker | F8: flach, Wind | G8: 🟢 | H8: 1 | J8: 5 | K8: 0 | L8: 1 | M8: 0 | N8: 0 | O8: 1 | P8: Teilweise | Q8: ~900 | R8: 2 | S8: 8 | T8: 2 | U8: 1 | V8: Hoch | W8: Klassiker-Kapitän, Edelhelfer, Sprinter | X8: Tratnik, Meeus, van Dijke
A9: Strade Bianche | C9: A | D9: 07.03.2026 | E9: Klassiker | F9: Schotter | G9: 🔴 | H9: 1 | J9: 8 | K9: 1 | L9: 0 | M9: 1 | N9: 0 | O9: 0 | P9: Nein | Q9: ~1800 | R9: 7 | S9: 4 | T9: 7 | U9: 1 | V9: Mittel | W9: Klassiker-Kapitän, Kapitän oder Co-Leader | X9: Roglic, Hindley, Pellizzari, Tratnik
A10: Paris–Nice | C10: A | D10: 08.03.-15.03.2026 | E10: WorldTour | F10: Allround | G10: 🔴 🟡 🟢 | H10: 8 | J10: 8 | K10: 2 | L10: 3 | M10: 3 | N10: 2 | O10: 3 | P10: Nein | Q10: ~20000 | R10: 7 | S10: 6 | T10: 6 | U10: 5 | V10: Mittel | W10: Kapitän o. Co-Leader, Edelhelfer, Sprinter | X10: Lipowitz, Cattaneo
A11: Tirreno–Adriatico | C11: A | D11: 09.03.-15.03.2026 | E11: WorldTour | F11: Allround | G11: 🔴 🟡 🟢 | H11: 7 | J11: 8 | K11: 2 | L11: 3 | M11: 2 | N11: 2 | O11: 3 | P11: Nein | Q11: ~22000 | R11: 7 | S11: 6 | T11: 6 | U11: 5 | V11: Mittel | W11: Kapitän o. Co-Leader, Edelhelfer, Sprinter | X11: Roglic, Hindley, Pellizzari, Tratnik
A12: Milano–Sanremo | C12: A+ | D12: 21.03.2026 | E12: Monument | F12: Sprintklassiker | G12: 🟢 | H12: 1 | J12: 7 | K12: 0 | L12: 1 | M12: 0 | N12: 0 | O12: 1 | P12: Nein | Q12: ~2000 | R12: 3 | S12: 10 | T12: 5 | U12: 1 | V12: Mittel | W12: Sprinter, Klassiker-Kapitän, kapitän | X12: Vermeersch, Pithie, van Poppel, Meeus
A13: Volta a Catalunya | C13: A | D13: 23.03.-29.03.2026 | E13: WorldTour | F13: Berge | G13: 🔴 🟡 🟢 | H13: 7 | J13: 8 | K13: 3 | L13: 1 | M13: 4 | N13: 2 | O13: 1 | P13: Nein | Q13: ~25000 | R13: 9 | S13: 4 | T13: 6 | U13: 3 | V13: Niedrig | W13: Kapitän o. Co-Leader, Edelhelfer, | X13: Hindley, Pellizzari, Aleotti
A14: Rounde de Brugge | C14: C | D14: 25.03.2026 | E14: Klassiker | F14: Pflaster+Wind | G14: 🟢 | H14: 1 | J14: 5 | K14: 0 | L14: 1 | M14: 0 | N14: 0 | O14: 1 | P14: Teilweise | Q14: ~1000 | R14: 3 | S14: 7 | T14: 3 | U14: 1 | V14: Hoch | W14: Sprinter, Edelhelfer,Klassiker-Kapitän, Co-Leader,
A15: E3 Classic | C15: A | D15: 27.03.2026 | E15: Klassiker | F15: Pflaster | G15: 🟡 | H15: 1 | J15: 8 | K15: 0 | L15: 1 | M15: 0 | N15: 1 | O15: 0 | P15: Ja | Q15: ~2000 | R15: 7 | S15: 5 | T15: 7 | U15: 1 | V15: Mittel | W15: Klassiker-Kapitän, Edelhelfer | X15: Pithie, Meeus
A16: Gent–Wevelgem | C16: B | D16: 29.03.2026 | E16: Klassiker | F16: Wind+Sprint | G16: 🟢 | H16: 1 | J16: 6 | K16: 0 | L16: 1 | M16: 0 | N16: 0 | O16: 1 | P16: Teilweise | Q16: ~1500 | R16: 3 | S16: 9 | T16: 4 | U16: 1 | V16: Hoch | W16: Sprinter, Klassiker-Kapitän | X16: Pithie, Meeus
A17: Dwars door Vlaanderen | C17: B | D17: 01.04.2026 | E17: Klassiker | F17: intensiv | G17: 🟡 | H17: 1 | J17: 6 | K17: 0 | L17: 1 | M17: 0 | N17: 1 | O17: 0 | P17: Ja | Q17: ~1300 | R17: 5 | S17: 6 | T17: 5 | U17: 1 | V17: Mittel | W17: Klassiker-Kapitän, Edelhelfer,Sprinter | X17: Pithie, Meeus, van Dijke
A18: Tour of Flanders | C18: A+ | D18: 05.04.2026 | E18: Monument | F18: Hügel+Pflaster | G18: 🟡 | H18: 1 | J18: 9 | K18: 0 | L18: 1 | M18: 0 | N18: 1 | O18: 0 | P18: Ja | Q18: ~2500 | R18: 7 | S18: 4 | T18: 9 | U18: 1 | V18: Hoch | W18: Klassiker-Kapitän, Edelhelfer | X18: Vermeersch, Pithie, van Poppel
A19: Basque Country | C19: A | D19: 06.04.-11.04.2026 | E19: WorldTour | F19: steile Berge | G19: 🔴 🟡 🟢 | H19: 6 | J19: 8 | K19: 3 | L19: 1 | M19: 4 | N19: 1 | O19: 1 | P19: Nein | Q19: ~18000 | R19: 9 | S19: 2 | T19: 8 | U19: 3 | V19: Niedrig | W19: Kapitän o. Co-Leader, Edelhelfer, | X19: Vlasov, Martínez
A20: Paris–Roubaix | C20: A+ | D20: 12.04.2026 | E20: Monument | F20: Pflaster | G20: 🟢 | H20: 1 | J20: 9 | K20: 0 | L20: 1 | M20: 0 | N20: 0 | O20: 1 | P20: Ja | Q20: ~1500 | R20: 3 | S20: 6 | T20: 2 | U20: 1 | V20: Hoch | W20: Klassiker-Kapitän, Edelhelfer | X20: Pithie, van Poppel, Meeus, van Dijke
A21: Amstel Gold | C21: A | D21: 19.04.2026 | E21: Klassiker | F21: hügelig | G21: 🔴 | H21: 1 | J21: 8 | K21: 1 | L21: 0 | M21: 1 | N21: 0 | O21: 0 | P21: Nein | Q21: ~3500 | R21: 8 | S21: 3 | T21: 9 | U21: 1 | V21: Niedrig | W21: Klassiker-Kapitän, Co-Leader | X21: Van Gils, Fisher-Black
A22: Tour of the Alpes | C22: D | D22: 20.04.-24.04.2026 | E22: 2.Pro | F22: Hochgebirge | G22: 🔴 🟡 🟢 | H22: 5 | J22: 7 | K22: 3 | L22: 1 | M22: 3 | N22: 1 | O22: 1 | P22: Nein | Q22: ~12000 | R22: 8 | S22: 3 | T22: 6 | U22: 2 | V22: Niedrig | W22: Co-Leader, Helfer | X22: Hindley, Pellizzari, Aleotti
A23: Flèche Wallonne | C23: A | D23: 22.04.2026 | E23: Klassiker | F23: steile Rampen | G23: 🔴 | H23: 1 | J23: 7 | K23: 1 | L23: 0 | M23: 1 | N23: 0 | O23: 0 | P23: Nein | Q23: ~3000 | R23: 9 | S23: 2 | T23: 9 | U23: 1 | V23: Niedrig | W23: Klassiker-Kapitän, Co-Leader | X23: Van Gils
A24: Liège–Bastogne–Liège | C24: A+ | D24: 26.04.2026 | E24: Monument | F24: Ardennen | G24: 🔴 | H24: 1 | J24: 9 | K24: 1 | L24: 0 | M24: 1 | N24: 0 | O24: 0 | P24: Nein | Q24: ~4500 | R24: 9 | S24: 2 | T24: 9 | U24: 1 | V24: Niedrig | W24: Kapitän, Klassiker-Kapitän, | X24: Van Gils, Fisher-Black
A25: Tour de Romandie | C25: B | D25: 28.04.-03.05.2026 | E25: WorldTour | F25: hügelig | G25: 🔴 🟡 🟢 | H25: 6 | J25: 7 | K25: 2 | L25: 2 | M25: 2 | N25: 2 | O25: 2 | P25: Nein | Q25: ~15000 | R25: 7 | S25: 4 | T25: 7 | U25: 4 | V25: Niedrig | W25: Kapitän oder Co-Leader, Sprinter, Edelhelfer | X25: Roglic, Pellizzari, Fisher-Black
A26: Eschborn-Frankfurt | C26: C | D26: 01.05.2026 | E26: WorldTour | F26: hügelig | G26: 🟡 | H26: 1 | J26: 6 | K26: 0 | L26: 1 | M26: 0 | N26: 1 | O26: 0 | P26: Nein | Q26: ~2000 | R26: 6 | S26: 6 | T26: 6 | U26: 1 | V26: Mittel | W26: Sprinter, Klassiker-Kapitän, Helfer
A27: Giro d’Italia | C27: A+ | D27: 09.05.-31.05.2026 | E27: Grand Tour | F27: extrem Hochgebirge | G27: 🔴 🟡 🟢 | H27: 21 | J27: 10 | K27: 7 | L27: 6 | M27: 9 | N27: 5 | O27: 7 | P27: Nein | Q27: ~52000 | R27: 10 | S27: 3 | T27: 6 | U27: 5 | V27: Niedrig | W27: Kapitäne, Sprinter, Edelhelfer | X27: Roglic, Moscon, Hindley, Pellizzari, Martínez, Tratnik, Aleotti, Denz
A28: Tour de Slovenia | C28: D | D28: 17.06.-21.06.2026 | E28: 2.Pro | F28: Hochgebirge | G28: 🔴 🟡 🟢 | H28: 5 | J28: 7 | K28: 2 | L28: 1 | M28: 3 | N28: 1 | O28: 1 | P28: Nein | Q28: ~13000 | R28: 8 | S28: 3 | T28: 7 | U28: 3 | V28: Niedrig | W28: Co-Leader, Helfer | X28: Aleotti
A29: Criterium de Dauphine | C29: B | D29: 07.06.-14.06.2026 | E29: WorldTour | F29: Mittelgebirge | G29: 🔴 🟡 🟢 | H29: 8 | J29: 8 | K29: 3 | L29: 2 | M29: 4 | N29: 2 | O29: 2 | P29: Nein | Q29: ~30000 | R29: 9 | S29: 4 | T29: 6 | U29: 5 | V29: Niedrig | W29: Kapitän oder Co-Leader, Sprinter, Edelhelfer | X29: Lipowitz, Evenepoel, Van Gils, Fisher-Black, Pithie, van Dijke, Zwiehoff, Hajek
A30: Tour de Suisse | C30: B | D30: 17.06.-21.06.2026 | E30: WorldTour | F30: Hochgebirge | G30: 🔴 🟡 🟢 | H30: 5 | J30: 8 | K30: 3 | L30: 1 | M30: 3 | N30: 1 | O30: 1 | P30: Nein | Q30: ~30000 | R30: 9 | S30: 4 | T30: 6 | U30: 5 | V30: Niedrig | W30: Kapitän oder Co-Leader, Sprinter, Edelhelfer | X30: Pellizzari, van Poppel, Meeus
A31: National Championships | C31: B | E31: Meisterschaft | F31: variabel | G31: 🟡 | H31: 1 | J31: 5 | K31: 0 | L31: 0 | M31: 0 | N31: 1 | O31: 0 | P31: Nein | Q31: variabel | R31: 5 | S31: 6 | T31: 5 | U31: 3 | V31: Mittel | W31: Alle Fahrertypen | X31: Lipowitz, van Poppel, Meeus, Hajek
A32: Tour de France | C32: A+ | D32: 04.07.-26.07.2026 | E32: Grand Tour | F32: Hochgebirge+TT | G32: 🔴 🟡 🟢 | H32: 21 | J32: 10 | K32: 6 | L32: 6 | M32: 8 | N32: 5 | O32: 8 | P32: Nein | Q32: ~50000 | R32: 10 | S32: 4 | T32: 7 | U32: 6 | V32: Mittel | W32: Kapitäne, Sprinter, Edelhelfer | X32: Roglic, Lipowitz, Evenepoel, Moscon, Vlasov, Cattaneo, Pithie, van Poppel, Meeus, van Dijke
A33: San Sebastian | C33: A | D33: 01.08.2026 | E33: Klassiker | F33: hügelig, Baskenland | G33: 🔴 | H33: 1 | J33: 8 | K33: 1 | L33: 0 | M33: 1 | N33: 0 | O33: 0 | P33: Nein | Q33: ~3300 | R33: 8 | S33: 3 | T33: 8 | U33: 1 | V33: Niedrig | W33: Klassiker-Kapitän, Kapitän oder Co-Leader | X33: Pellizzari, Vlasov, Van Gils, Aleotti, Denz, Zwiehoff
A34: Tour de Pologne | C34: C | D34: 03.08.-09.08.2026 | E34: WorldTour | F34: hügelig | G34: 🔴 🟡 🟢 | H34: 7 | J34: 6 | K34: 2 | L34: 3 | M34: 2 | N34: 2 | O34: 3 | P34: Nein | Q34: ~9000 | R34: 6 | S34: 5 | T34: 6 | U34: 3 | V34: Mittel | W34: Sprinter, Helfer, Co-Leader,
A35: Tour de Denmark | C35: C | D35: 11.08.-15.08.2026 | E35: 2.Pro | F35: flach/hügelig | G35: 🟡 🟢 | H35: 5 | J35: 5 | K35: 0 | L35: 3 | M35: 0 | N35: 2 | O35: 3 | P35: Nein | Q35: ~6500 | R35: 3 | S35: 8 | T35: 5 | U35: 2 | V35: Mittel | W35: Sprinter, Klassiker-Kapitän, Helfer, Ausreißer
A36: ADAC Cyclassics Hamburg | C36: A | D36: 16.08.2026 | E36: WorldTour | F36: flach/sprint | G36: 🟢 | H36: 1 | J36: 4 | K36: 0 | L36: 1 | M36: 0 | N36: 0 | O36: 1 | P36: Nein | Q36: ~1500 | R36: 2 | S36: 9 | T36: 3 | U36: 1 | V36: Mittel | W36: Sprinter, Klassiker-Kapitän, Helfer | X36: Meeus, van Poppel, Pithie, van Dijke, Marit
A37: LIDL Deutschland Tour | C37: D | D37: 19.08.-23.08.2026 | E37: 2.Pro | F37: gemischt | G37: 🔴 🟡 🟢 | H37: 5 | J37: 6 | K37: 1 | L37: 2 | M37: 1 | N37: 2 | O37: 2 | P37: Nein | Q37: ~10000 | R37: 6 | S37: 6 | T37: 6 | U37: 3 | V37: Mittel | W37: Sprinter, Helfer,Co-Leader, Ausreißer
A38: Renewl Tour | C38: C | D38: 19.08.-23.08.2026 | E38: WorldTour | F38: gemischt | G38: 🔴 🟡 🟢 | H38: 6 | J38: 5 | K38: 1 | L38: 3 | M38: 1 | N38: 2 | O38: 3 | P38: Nein | Q38: ~8000 | R38: 5 | S38: 6 | T38: 5 | U38: 2 | V38: Mittel | W38: Sprinter, Helfer,Klassiker-Kapitän, Co-Leader, | X38: Van Gils, van Dijke
A39: Vuelta a España | C39: A+ | D39: 22.08.-13.09.2026 | E39: Grand Tour | F39: steile Berge | G39: 🔴 🟡 🟢 | H39: 21 | J39: 9 | K39: 9 | L39: 5 | M39: 9 | N39: 6 | O39: 6 | P39: Nein | Q39: ~45000 | R39: 9 | S39: 3 | T39: 7 | U39: 4 | V39: Mittel | W39: Kapitän, Sprinter, Edelhelfer | X39: Hindley, Pellizzari, Fisher-Black, van Dijke, Aleotti, Denz, Zwiehoff
A40: Bretagne Classic | C40: B | D40: 30.08.2026 | E40: WorldTour | F40: hügelig, Küste | G40: 🔴 🟡 | H40: 1 | J40: 7 | K40: 1 | L40: 0 | M40: 0 | N40: 1 | O40: 0 | P40: Nein | Q40: ~2800 | R40: 6 | S40: 5 | T40: 7 | U40: 1 | V40: Hoch | W40: Klassiker-Kapitän, Sprinter
...

Sheet Fahreranalyse
A1: Fahreranalyse
A3: Name | C3: Fahrerrolle | D3: Fahrertyp | E3: Bevorzugte Rennen | G3: Größe (cm) | H3: Gewicht (kg) | I3: Alter | J3: Renntage aktuelle Saison | K3: Teilnahmen letzte Saison | L3: Nationalität | M3: Höhen-/Hitzetauglichkeit | N3: Regenerationsbedarf n. GT (in Tagen) | O3: Formkurve/Saisonziel-Fenster | P3: Rennen in der Vergangenheit (Palmarès/Historie)
A4: =IF(Fahrerwerte!A4="","",Fahrerwerte!A4) | C4: =IF(Fahrerwerte!P4="","",Fahrerwerte!P4) | D4: Gesamtfahrer, Klassikerfahrer, Bergfahrer | E4: =IF(Fahrerwerte!Q4="","",Fahrerwerte!Q4) | G4: 171 | H4: =IF(OR(C4="Helfer",C4="Wasserträger"),65,68) | I4: 26 | J4: =IFERROR(INDEX(Planung!$B$7:$B$36,MATCH(A4,Planung!$A$7:$A$36,0)),"") | K4: 58 | L4: BEL | M4: Hoch | N4: 18 | O4: März/April Klassiker + Mai/Juli-Peak (Giro & Tour de France) | P4: 2x Olympiasieger 2024 (Strasse/Zeitfahren), Weltmeister Strasse 2022, 3x Weltmeister Zeitfahren, Vuelta-Sieger 2022, 2x Liege-Bastogne-Liege
A5: =IF(Fahrerwerte!A5="","",Fahrerwerte!A5) | C5: =IF(Fahrerwerte!P5="","",Fahrerwerte!P5) | D5: Gesamtfahrer, Etappenfahrer, Bergfahrer | E5: =IF(Fahrerwerte!Q5="","",Fahrerwerte!Q5) | G5: 177 | H5: =IF(OR(C5="Helfer",C5="Wasserträger"),65,68) | I5: 36 | J5: =IFERROR(INDEX(Planung!$B$7:$B$36,MATCH(A5,Planung!$A$7:$A$36,0)),"") | K5: 55 | L5: SLO | M5: Hoch | N5: 18 | O5: Mai/September (Giro & Vuelta) | P5: 4x Vuelta a Espana-Sieger, Giro d'Italia-Sieger 2023, zahlreiche Grand-Tour-Etappensiege
A6: =IF(Fahrerwerte!A6="","",Fahrerwerte!A6) | C6: =IF(Fahrerwerte!P6="","",Fahrerwerte!P6) | D6: Gesamtfahrer, Etappenfahrer, Bergfahrer | E6: =IF(Fahrerwerte!Q6="","",Fahrerwerte!Q6) | G6: 181 | H6: =IF(OR(C6="Helfer",C6="Wasserträger"),65,68) | I6: 25 | J6: =IFERROR(INDEX(Planung!$B$7:$B$36,MATCH(A6,Planung!$A$7:$A$36,0)),"") | K6: 62 | L6: GER | M6: Mittel-Hoch | N6: 18 | O6: Mai/Juli-Peak (Giro & Tour de France) | P6: 3. Tour de France 2025 + Weisses Trikot, mehrere Top-3-Platzierungen in Rundfahrten
A7: =IF(Fahrerwerte!A7="","",Fahrerwerte!A7) | C7: =IF(Fahrerwerte!P7="","",Fahrerwerte!P7) | D7: Etappenfahrer, Allrounder, Bergfahrer | E7: =IF(Fahrerwerte!Q7="","",Fahrerwerte!Q7) | G7: 186 | H7: =IF(OR(C7="Helfer",C7="Wasserträger"),65,68) | I7: 30 | J7: =IFERROR(INDEX(Planung!$B$7:$B$36,MATCH(A7,Planung!$A$7:$A$36,0)),"") | K7: 58 | L7: RUS | M7: Mittel | N7: 18 | O7: Juli/September (Tour de France & Vuelta)+ GrandTourSupport | P7: Sieger Tour de Romandie 2022, Sieger Vuelta a la Comunitat Valenciana 2022
A8: =IF(Fahrerwerte!A8="","",Fahrerwerte!A8) | C8: =IF(Fahrerwerte!P8="","",Fahrerwerte!P8) | D8: Gesamtfahrer, Etappenfahrer, Bergfahrer | E8: =IF(Fahrerwerte!Q8="","",Fahrerwerte!Q8) | G8: 172 | H8: =IF(OR(C8="Helfer",C8="Wasserträger"),65,68) | I8: 30 | J8: =IFERROR(INDEX(Planung!$B$7:$B$36,MATCH(A8,Planung!$A$7:$A$36,0)),"") | K8: 60 | L8: COL | M8: Hoch | N8: 18 | O8: Juli/September (Tour de France & Vuelta)+ GrandTourSupport | P8: Sieger Criterium du Dauphine, Sieger Itzulia Basque Country
A9: =IF(Fahrerwerte!A9="","",Fahrerwerte!A9) | C9: =IF(Fahrerwerte!P9="","",Fahrerwerte!P9) | D9: Gesamtfahrer, Etappenfahrer, Bergfahrer | E9: =IF(Fahrerwerte!Q9="","",Fahrerwerte!Q9) | G9: 180 | H9: =IF(OR(C9="Helfer",C9="Wasserträger"),65,68) | I9: 30 | J9: =IFERROR(INDEX(Planung!$B$7:$B$36,MATCH(A9,Planung!$A$7:$A$36,0)),"") | K9: 55 | L9: AUS | M9: Mittel-Hoch | N9: 18 | O9: Mai/Juli-Peak (Giro & Tour de France)+ GrandTourSupport | P9: Giro d'Italia-Sieger 2022
A10: =IF(Fahrerwerte!A10="","",Fahrerwerte!A10) | C10: =IF(Fahrerwerte!P10="","",Fahrerwerte!P10) | D10: Etappenfahrer, Ausreißer, Bergfahrer | E10: =IF(Fahrerwerte!Q10="","",Fahrerwerte!Q10) | G10: 178 | H10: =IF(OR(C10="Helfer",C10="Wasserträger"),65,68) | I10: 22 | J10: =IFERROR(INDEX(Planung!$B$7:$B$36,MATCH(A10,Planung!$A$7:$A$36,0)),"") | K10: 65 | L10: ITA | M10: Mittel | N10: 18 | O10: Juli/September (Tour de France & Vuelta)+ GrandTourSupport | P10: Etappensieger Vuelta a Espana 2025, Platz 6 Giro d'Italia 2025
A11: =IF(Fahrerwerte!A11="","",Fahrerwerte!A11) | C11: =IF(Fahrerwerte!P11="","",Fahrerwerte!P11) | D11: Klassikerfahrer, Ausreißer, Bergfahrer | E11: =IF(Fahrerwerte!Q11="","",Fahrerwerte!Q11) | G11: 181 | H11: =IF(OR(C11="Helfer",C11="Wasserträger"),65,68) | I11: 26 | J11: =IFERROR(INDEX(Planung!$B$7:$B$36,MATCH(A11,Planung!$A$7:$A$36,0)),"") | K11: 68 | L11: BEL | M11: Mittel | N11: 16 | O11: März-April (Ardennen-Klassiker) Juli (Tour de France) | P11: Sieger Saudi Tour 2022, Top-3 bei mehreren Ardennen-Klassikern
A12: =IF(Fahrerwerte!A12="","",Fahrerwerte!A12) | C12: =IF(Fahrerwerte!P12="","",Fahrerwerte!P12) | D12: Allrounder, Etappenfahrer, Bergfahrer | E12: =IF(Fahrerwerte!Q12="","",Fahrerwerte!Q12) | G12: 173 | H12: =IF(OR(C12="Helfer",C12="Wasserträger"),65,68) | I12: 36 | J12: =IFERROR(INDEX(Planung!$B$7:$B$36,MATCH(A12,Planung!$A$7:$A$36,0)),"") | K12: 70 | L12: SLO | M12: Mittel | N12: 16 | O12: Februar-März (Frühjahrsklassiker) + GrandTourSupport | P12: Sieger Omloop Het Nieuwsblad 2024, Etappensieger Giro d'Italia
A13: =IF(Fahrerwerte!A13="","",Fahrerwerte!A13) | C13: =IF(Fahrerwerte!P13="","",Fahrerwerte!P13) | D13: Etappenfahrer, Allrounder, Bergfahrer | E13: =IF(Fahrerwerte!Q13="","",Fahrerwerte!Q13) | G13: 182 | H13: =IF(OR(C13="Helfer",C13="Wasserträger"),65,68) | I13: 35 | J13: =IFERROR(INDEX(Planung!$B$7:$B$36,MATCH(A13,Planung!$A$7:$A$36,0)),"") | K13: 65 | L13: ITA | M13: Mittel | N13: 14 | O13: Ganzjährig (Zeitfahr-Spezialeinsätze)+ GrandTourSupport | P13: Starker Zeitfahrspezialist, mehrfache Top-Ergebnisse im Zeitfahren
A14: =IF(Fahrerwerte!A14="","",Fahrerwerte!A14) | C14: =IF(Fahrerwerte!P14="","",Fahrerwerte!P14) | D14: Klassikerfahrer, Etappenfahrer, Bergfahrer | E14: =IF(Fahrerwerte!Q14="","",Fahrerwerte!Q14) | G14: 189 | H14: =IF(OR(C14="Helfer",C14="Wasserträger"),65,68) | I14: 24 | J14: =IFERROR(INDEX(Planung!$B$7:$B$36,MATCH(A14,Planung!$A$7:$A$36,0)),"") | K14: 60 | L14: NZL | M14: Mittel | N14: 16 | O14: März-April (Klassiker)+ GrandTourSupport | P14: Sieger Great Ocean Road Race 2024, neuseelaendischer Zeitfahrmeister
A15: =IF(Fahrerwerte!A15="","",Fahrerwerte!A15) | C15: =IF(Fahrerwerte!P15="","",Fahrerwerte!P15) | D15: Klassikerfahrer, Puncheur | E15: =IF(Fahrerwerte!Q15="","",Fahrerwerte!Q15) | G15: 173 | H15: =IF(OR(C15="Helfer",C15="Wasserträger"),65,68) | I15: 33 | J15: =IFERROR(INDEX(Planung!$B$7:$B$36,MATCH(A15,Planung!$A$7:$A$36,0)),"") | K15: 55 | L15: BEL | M15: Mittel | N15: 12 | O15: Februar-April (Kopfsteinpflaster-Klassiker)+ GrandTourSupport | P15: Weltmeister Gravel 2022, mehrfacher belgischer Cyclocross-Meister
... A33: =IF(Fahrerwerte!A33="","",Fahrerwerte!A33) | C33: =IF(Fahrerwerte!P33="","",Fahrerwerte!P33) | D33: Puncheur, Allrounder | E33: =IF(Fahrerwerte!Q33="","",Fahrerwerte!Q33) | G33: 186 | H33: =IF(OR(C33="Helfer",C33="Wasserträger"),65,68) | I33: 26 | J33: =IFERROR(INDEX(Planung!$B$7:$B$36,MATCH(A33,Planung!$A$7:$A$36,0)),"") | K33: 60 | L33: AUS | M33: Niedrig-Mittel | N33: 12 | O33: Ganzjährig (Klassiker- und Sprint-Support) | P33: 10. Etappenplatz Vuelta a Espana, vielseitiger Klassiker-Helfer

Sheet Fahrerbewertung
A1: Fahrerbewertung – Automatische Eignungsmatrix
A3: Fahrer | B3: Tour Down Under | C3: Tour of Oman | D3: UAE Tour | E3: Volta ao Algarve | F3: Vuelta a Andalucia | G3: Omloop Nieuwsblad | H3: Kuurne-Brussel-Kuurne | I3: Strade Bianche | J3: Paris-Nice | K3: Tirreno-Adriatico | L3: Milano-Sanremo | M3: Volta a Catalunya | N3: Ronde van Brugge | O3: E3 Classic | P3: Gent-Wevelgem | Q3: Dwars door Vlaanderen | R3: Ronde van Vlaanderen | S3: Izulia Basque Country | T3: Paris-Roubaix | U3: Amstel Gold Race | V3: Tour of the Alpes | W3: La Fleche Wallonne | X3: Liege-Bastogne-Liege | Y3: Tour de Romandie | Z3: Eschborn-Frankfurt | AA3: Giro d'Italia | AB3: Tour de Slovenia | AC3: Criterium de Dauphine | AD3: Tour de Suisse | AE3: National Championchips | AF3: Tour de France | AG3: San Sebastian | AH3: Tour de Pologne | AI3: Tour de Denmark | AJ3: ADAC Cyclassis Hamburg | AK3: LIDL Deutschland Tour | AL3: Renewl Tour | AM3: Vuelta a Espana | AN3: Bretagne Classic | AO3: GP Quebec | AP3: GP Montreal | AQ3: World Championships | AR3: European Championships | AS3: Il Lombardia | AT3: Tour de Changxi
A4: =IFERROR(Planung!A7,"") | B4: =IFERROR(ROUND((INDEX(Fahrerwerte!$C:$C,MATCH($A4,Fahrerwerte!$A:$A,0))*4+INDEX(Fahrerwerte!$I:$I,MATCH($A4,Fahrerwerte!$A:$A,0))*8+INDEX(Fahrerwerte!$E:$E,MATCH($A4,Fahrerwerte!$A:$A,0))*4+INDEX(Fahrerwerte!$F:$F,MATCH($A4,Fahrerwerte!$A:$A,0))*1)/17,0),"") | C4: =IFERROR(ROUND((INDEX(Fahrerwerte!$C:$C,MATCH($A4,Fahrerwerte!$A:$A,0))*5+INDEX(Fahrerwerte!$I:$I,MATCH($A4,Fahrerwerte!$A:$A,0))*6+INDEX(Fahrerwerte!$E:$E,MATCH($A4,Fahrerwerte!$A:$A,0))*5+INDEX(Fahrerwerte!$F:$F,MATCH($A4,Fahrerwerte!$A:$A,0))*2)/18,0),"") | D4: =IFERROR(ROUND((INDEX(Fahrerwerte!$C:$C,MATCH($A4,Fahrerwerte!$A:$A,0))*5+INDEX(Fahrerwerte!$I:$I,MATCH($A4,Fahrerwerte!$A:$A,0))*8+INDEX(Fahrerwerte!$E:$E,MATCH($A4,Fahrerwerte!$A:$A,0))*3+INDEX(Fahrerwerte!$F:$F,MATCH($A4,Fahrerwerte!$A:$A,0))*4)/20,0),"") | E4: =IFERROR(ROUND((INDEX(Fahrerwerte!$C:$C,MATCH($A4,Fahrerwerte!$A:$A,0))*6+INDEX(Fahrerwerte!$I:$I,MATCH($A4,Fahrerwerte!$A:$A,0))*5+INDEX(Fahrerwerte!$E:$E,MATCH($A4,Fahrerwerte!$A:$A,0))*6+INDEX(Fahrerwerte!$F:$F,MATCH($A4,Fahrerwerte!$A:$A,0))*3)/20,0),"") | F4: =IFERROR(ROUND((INDEX(Fahrerwerte!$C:$C,MATCH($A4,Fahrerwerte!$A:$A,0))*6+INDEX(Fahrerwerte!$I:$I,MATCH($A4,Fahrerwerte!$A:$A,0))*5+INDEX(Fahrerwerte!$E:$E,MATCH($A4,Fahrerwerte!$A:$A,0))*6+INDEX(Fahrerwerte!$F:$F,MATCH($A4,Fahrerwerte!$A:$A,0))*3)/20,0),"") | G4: =IFERROR(ROUND((INDEX(Fahrerwerte!$C:$C,MATCH($A4,Fahrerwerte!$A:$A,0))*5+INDEX(Fahrerwerte!$I:$I,MATCH($A4,Fahrerwerte!$A:$A,0))*6+INDEX(Fahrerwerte!$E:$E,MATCH($A4,Fahrerwerte!$A:$A,0))*5+INDEX(Fahrerwerte!$F:$F,MATCH($A4,Fahrerwerte!$A:$A,0))*1)/17,0),"") | H4: =IFERROR(ROUND((INDEX(Fahrerwerte!$C:$C,MATCH($A4,Fahrerwerte!$A:$A,0))*2+INDEX(Fahrerwerte!$I:$I,MATCH($A4,Fahrerwerte!$A:$A,0))*8+INDEX(Fahrerwerte!$E:$E,MATCH($A4,Fahrerwerte!$A:$A,0))*2+INDEX(Fahrerwerte!$F:$F,MATCH($A4,Fahrerwerte!$A:$A,0))*1)/13,0),"") | I4: =IFERROR(ROUND((INDEX(Fahrerwerte!$C:$C,MATCH($A4,Fahrerwerte!$A:$A,0))*7+INDEX(Fahrerwerte!$I:$I,MATCH($A4,Fahrerwerte!$A:$A,0))*4+INDEX(Fahrerwerte!$E:$E,MATCH($A4,Fahrerwerte!$A:$A,0))*7+INDEX(Fahrerwerte!$F:$F,MATCH($A4,Fahrerwerte!$A:$A,0))*1)/19,0),"") | J4: =IFERROR(ROUND((INDEX(Fahrerwerte!$C:$C,MATCH($A4,Fahrerwerte!$A:$A,0))*7+INDEX(Fahrerwerte!$I:$I,MATCH($A4,Fahrerwerte!$A:$A,0))*6+INDEX(Fahrerwerte!$E:$E,MATCH($A4,Fahrerwerte!$A:$A,0))*6+INDEX(Fahrerwerte!$F:$F,MATCH($A4,Fahrerwerte!$A:$A,0))*5)/24,0),"") | K4: =IFERROR(ROUND((INDEX(Fahrerwerte!$C:$C,MATCH($A4,Fahrerwerte!$A:$A,0))*7+INDEX(Fahrerwerte!$I:$I,MATCH($A4,Fahrerwerte!$A:$A,0))*6+INDEX(Fahrerwerte!$E:$E,MATCH($A4,Fahrerwerte!$A:$A,0))*6+INDEX(Fahrerwerte!$F:$F,MATCH($A4,Fahrerwerte!$A:$A,0))*5)/24,0),"") | L4: =IFERROR(ROUND((INDEX(Fahrerwerte!$C:$C,MATCH($A4,Fahrerwerte!$A:$A,0))*3+INDEX(Fahrerwerte!$I:$I,MATCH($A4,Fahrerwerte!$A:$A,0))*10+INDEX(Fahrerwerte!$E:$E,MATCH($A4,Fahrerwerte!$A:$A,0))*5+INDEX(Fahrerwerte!$F:$F,MATCH($A4,Fahrerwerte!$A:$A,0))*1)/19,0),"") | M4: =IFERROR(ROUND((INDEX(Fahrerwerte!$C:$C,MATCH($A4,Fahrerwerte!$A:$A,0))*9+INDEX(Fahrerwerte!$I:$I,MATCH($A4,Fahrerwerte!$A:$A,0))*4+INDEX(Fahrerwerte!$E:$E,MATCH($A4,Fahrerwerte!$A:$A,0))*6+INDEX(Fahrerwerte!$F:$F,MATCH($A4,Fahrerwerte!$A:$A,0))*3)/22,0),"") | N4: =IFERROR(ROUND((INDEX(Fahrerwerte!$C:$C,MATCH($A4,Fahrerwerte!$A:$A,0))*3+INDEX(Fahrerwerte!$I:$I,MATCH($A4,Fahrerwerte!$A:$A,0))*7+INDEX(Fahrerwerte!$E:$E,MATCH($A4,Fahrerwerte!$A:$A,0))*3+INDEX(Fahrerwerte!$F:$F,MATCH($A4,Fahrerwerte!$A:$A,0))*1)/14,0),"") | O4: =IFERROR(ROUND((INDEX(Fahrerwerte!$C:$C,MATCH($A4,Fahrerwerte!$A:$A,0))*7+INDEX(Fahrerwerte!$I:$I,MATCH($A4,Fahrerwerte!$A:$A,0))*5+INDEX(Fahrerwerte!$E:$E,MATCH($A4,Fahrerwerte!$A:$A,0))*7+INDEX(Fahrerwerte!$F:$F,MATCH($A4,Fahrerwerte!$A:$A,0))*1)/20,0),"") | P4: =IFERROR(ROUND((INDEX(Fahrerwerte!$C:$C,MATCH($A4,Fahrerwerte!$A:$A,0))*3+INDEX(Fahrerwerte!$I:$I,MATCH($A4,Fahrerwerte!$A:$A,0))*9+INDEX(Fahrerwerte!$E:$E,MATCH($A4,Fahrerwerte!$A:$A,0))*4+INDEX(Fahrerwerte!$F:$F,MATCH($A4,Fahrerwerte!$A:$A,0))*1)/17,0),"") | Q4: =IFERROR(ROUND((INDEX(Fahrerwerte!$C:$C,MATCH($A4,Fahrerwerte!$A:$A,0))*5+INDEX(Fahrerwerte!$I:$I,MATCH($A4,Fahrerwerte!$A:$A,0))*6+INDEX(Fahrerwerte!$E:$E,MATCH($A4,Fahrerwerte!$A:$A,0))*5+INDEX(Fahrerwerte!$F:$F,MATCH($A4,Fahrerwerte!$A:$A,0))*1)/17,0),"") | R4: =IFERROR(ROUND((INDEX(Fahrerwerte!$C:$C,MATCH($A4,Fahrerwerte!$A:$A,0))*7+INDEX(Fahrerwerte!$I:$I,MATCH($A4,Fahrerwerte!$A:$A,0))*4+INDEX(Fahrerwerte!$E:$E,MATCH($A4,Fahrerwerte!$A:$A,0))*9+INDEX(Fahrerwerte!$F:$F,MATCH($A4,Fahrerwerte!$A:$A,0))*1)/21,0),"") | S4: =IFERROR(ROUND((INDEX(Fahrerwerte!$C:$C,MATCH($A4,Fahrerwerte!$A:$A,0))*9+INDEX(Fahrerwerte!$I:$I,MATCH($A4,Fahrerwerte!$A:$A,0))*2+INDEX(Fahrerwerte!$E:$E,MATCH($A4,Fahrerwerte!$A:$A,0))*8+INDEX(Fahrerwerte!$F:$F,MATCH($A4,Fahrerwerte!$A:$A,0))*3)/22,0),"") | T4: =IFERROR(ROUND((INDEX(Fahrerwerte!$C:$C,MATCH($A4,Fahrerwerte!$A:$A,0))*3+INDEX(Fahrerwerte!$I:$I,MATCH($A4,Fahrerwerte!$A:$A,0))*6+INDEX(Fahrerwerte!$E:$E,MATCH($A4,Fahrerwerte!$A:$A,0))*2+INDEX(Fahrerwerte!$F:$F,MATCH($A4,Fahrerwerte!$A:$A,0))*1)/12,0),"") | U4: =IFERROR(ROUND((INDEX(Fahrerwerte!$C:$C,MATCH($A4,Fahrerwerte!$A:$A,0))*8+INDEX(Fahrerwerte!$I:$I,MATCH($A4,Fahrerwerte!$A:$A,0))*3+INDEX(Fahrerwerte!$E:$E,MATCH($A4,Fahrerwerte!$A:$A,0))*9+INDEX(Fahrerwerte!$F:$F,MATCH($A4,Fahrerwerte!$A:$A,0))*1)/21,0),"") | V4: =IFERROR(ROUND((INDEX(Fahrerwerte!$C:$C,MATCH($A4,Fahrerwerte!$A:$A,0))*8+INDEX(Fahrerwerte!$I:$I,MATCH($A4,Fahrerwerte!$A:$A,0))*3+INDEX(Fahrerwerte!$E:$E,MATCH($A4,Fahrerwerte!$A:$A,0))*6+INDEX(Fahrerwerte!$F:$F,MATCH($A4,Fahrerwerte!$A:$A,0))*2)/19,0),"") | W4: =IFERROR(ROUND((INDEX(Fahrerwerte!$C:$C,MATCH($A4,Fahrerwerte!$A:$A,0))*9+INDEX(Fahrerwerte!$I:$I,MATCH($A4,Fahrerwerte!$A:$A,0))*2+INDEX(Fahrerwerte!$E:$E,MATCH($A4,Fahrerwerte!$A:$A,0))*9+INDEX(Fahrerwerte!$F:$F,MATCH($A4,Fahrerwerte!$A:$A,0))*1)/21,0),"") | X4: =IFERROR(ROUND((INDEX(Fahrerwerte!$C:$C,MATCH($A4,Fahrerwerte!$A:$A,0))*9+INDEX(Fahrerwerte!$I:$I,MATCH($A4,Fahrerwerte!$A:$A,0))*2+INDEX(Fahrerwerte!$E:$E,MATCH($A4,Fahrerwerte!$A:$A,0))*9+INDEX(Fahrerwerte!$F:$F,MATCH($A4,Fahrerwerte!$A:$A,0))*1)/21,0),"") | Y4: =IFERROR(ROUND((INDEX(Fahrerwerte!$C:$C,MATCH($A4,Fahrerwerte!$A:$A,0))*7+INDEX(Fahrerwerte!$I:$I,MATCH($A4,Fahrerwerte!$A:$A,0))*4+INDEX(Fahrerwerte!$E:$E,MATCH($A4,Fahrerwerte!$A:$A,0))*7+INDEX(Fahrerwerte!$F:$F,MATCH($A4,Fahrerwerte!$A:$A,0))*4)/22,0),"") | Z4: =IFERROR(ROUND((INDEX(Fahrerwerte!$C:$C,MATCH($A4,Fahrerwerte!$A:$A,0))*6+INDEX(Fahrerwerte!$I:$I,MATCH($A4,Fahrerwerte!$A:$A,0))*6+INDEX(Fahrerwerte!$E:$E,MATCH($A4,Fahrerwerte!$A:$A,0))*6+INDEX(Fahrerwerte!$F:$F,MATCH($A4,Fahrerwerte!$A:$A,0))*1)/19,0),"") | AA4: =IFERROR(ROUND((INDEX(Fahrerwerte!$C:$C,MATCH($A4,Fahrerwerte!$A:$A,0))*10+INDEX(Fahrerwerte!$I:$I,MATCH($A4,Fahrerwerte!$A:$A,0))*3+INDEX(Fahrerwerte!$E:$E,MATCH($A4,Fahrerwerte!$A:$A,0))*6+INDEX(Fahrerwerte!$F:$F,MATCH($A4,Fahrerwerte!$A:$A,0))*5)/24,0),"") | AB4: =IFERROR(ROUND((INDEX(Fahrerwerte!$C:$C,MATCH($A4,Fahrerwerte!$A:$A,0))*8+INDEX(Fahrerwerte!$I:$I,MATCH($A4,Fahrerwerte!$A:$A,0))*3+INDEX(Fahrerwerte!$E:$E,MATCH($A4,Fahrerwerte!$A:$A,0))*7+INDEX(Fahrerwerte!$F:$F,MATCH($A4,Fahrerwerte!$A:$A,0))*3)/21,0),"") | AC4: =IFERROR(ROUND((INDEX(Fahrerwerte!$C:$C,MATCH($A4,Fahrerwerte!$A:$A,0))*7+INDEX(Fahrerwerte!$I:$I,MATCH($A4,Fahrerwerte!$A:$A,0))*3+INDEX(Fahrerwerte!$E:$E,MATCH($A4,Fahrerwerte!$A:$A,0))*7+INDEX(Fahrerwerte!$F:$F,MATCH($A4,Fahrerwerte!$A:$A,0))*2)/19,0),"") | AD4: =IFERROR(ROUND((INDEX(Fahrerwerte!$C:$C,MATCH($A4,Fahrerwerte!$A:$A,0))*9+INDEX(Fahrerwerte!$I:$I,MATCH($A4,Fahrerwerte!$A:$A,0))*4+INDEX(Fahrerwerte!$E:$E,MATCH($A4,Fahrerwerte!$A:$A,0))*6+INDEX(Fahrerwerte!$F:$F,MATCH($A4,Fahrerwerte!$A:$A,0))*5)/24,0),"") | AE4: =IFERROR(ROUND((INDEX(Fahrerwerte!$C:$C,MATCH($A4,Fahrerwerte!$A:$A,0))*5+INDEX(Fahrerwerte!$I:$I,MATCH($A4,Fahrerwerte!$A:$A,0))*6+INDEX(Fahrerwerte!$E:$E,MATCH($A4,Fahrerwerte!$A:$A,0))*5+INDEX(Fahrerwerte!$F:$F,MATCH($A4,Fahrerwerte!$A:$A,0))*3)/19,0),"") | AF4: =IFERROR(ROUND((INDEX(Fahrerwerte!$C:$C,MATCH($A4,Fahrerwerte!$A:$A,0))*10+INDEX(Fahrerwerte!$I:$I,MATCH($A4,Fahrerwerte!$A:$A,0))*4+INDEX(Fahrerwerte!$E:$E,MATCH($A4,Fahrerwerte!$A:$A,0))*7+INDEX(Fahrerwerte!$F:$F,MATCH($A4,Fahrerwerte!$A:$A,0))*6)/27,0),"") | AG4: =IFERROR(ROUND((INDEX(Fahrerwerte!$C:$C,MATCH($A4,Fahrerwerte!$A:$A,0))*8+INDEX(Fahrerwerte!$I:$I,MATCH($A4,Fahrerwerte!$A:$A,0))*3+INDEX(Fahrerwerte!$E:$E,MATCH($A4,Fahrerwerte!$A:$A,0))*8+INDEX(Fahrerwerte!$F:$F,MATCH($A4,Fahrerwerte!$A:$A,0))*1)/20,0),"") | AH4: =IFERROR(ROUND((INDEX(Fahrerwerte!$C:$C,MATCH($A4,Fahrerwerte!$A:$A,0))*6+INDEX(Fahrerwerte!$I:$I,MATCH($A4,Fahrerwerte!$A:$A,0))*5+INDEX(Fahrerwerte!$E:$E,MATCH($A4,Fahrerwerte!$A:$A,0))*6+INDEX(Fahrerwerte!$F:$F,MATCH($A4,Fahrerwerte!$A:$A,0))*3)/20,0),"") | AI4: =IFERROR(ROUND((INDEX(Fahrerwerte!$C:$C,MATCH($A4,Fahrerwerte!$A:$A,0))*3+INDEX(Fahrerwerte!$I:$I,MATCH($A4,Fahrerwerte!$A:$A,0))*8+INDEX(Fahrerwerte!$E:$E,MATCH($A4,Fahrerwerte!$A:$A,0))*5+INDEX(Fahrerwerte!$F:$F,MATCH($A4,Fahrerwerte!$A:$A,0))*2)/18,0),"") | AJ4: =IFERROR(ROUND((INDEX(Fahrerwerte!$C:$C,MATCH($A4,Fahrerwerte!$A:$A,0))*2+INDEX(Fahrerwerte!$I:$I,MATCH($A4,Fahrerwerte!$A:$A,0))*9+INDEX(Fahrerwerte!$E:$E,MATCH($A4,Fahrerwerte!$A:$A,0))*2+INDEX(Fahrerwerte!$F:$F,MATCH($A4,Fahrerwerte!$A:$A,0))*1)/14,0),"") | AK4: =IFERROR(ROUND((INDEX(Fahrerwerte!$C:$C,MATCH($A4,Fahrerwerte!$A:$A,0))*6+INDEX(Fahrerwerte!$I:$I,MATCH($A4,Fahrerwerte!$A:$A,0))*6+INDEX(Fahrerwerte!$E:$E,MATCH($A4,Fahrerwerte!$A:$A,0))*6+INDEX(Fahrerwerte!$F:$F,MATCH($A4,Fahrerwerte!$A:$A,0))*3)/21,0),"") | AL4: =IFERROR(ROUND((INDEX(Fahrerwerte!$C:$C,MATCH($A4,Fahrerwerte!$A:$A,0))*5+INDEX(Fahrerwerte!$I:$I,MATCH($A4,Fahrerwerte!$A:$A,0))*6+INDEX(Fahrerwerte!$E:$E,MATCH($A4,Fahrerwerte!$A:$A,0))*5+INDEX(Fahrerwerte!$F:$F,MATCH($A4,Fahrerwerte!$A:$A,0))*2)/18,0),"") | AM4: =IFERROR(ROUND((INDEX(Fahrerwerte!$C:$C,MATCH($A4,Fahrerwerte!$A:$A,0))*9+INDEX(Fahrerwerte!$I:$I,MATCH($A4,Fahrerwerte!$A:$A,0))*3+INDEX(Fahrerwerte!$E:$E,MATCH($A4,Fahrerwerte!$A:$A,0))*7+INDEX(Fahrerwerte!$F:$F,MATCH($A4,Fahrerwerte!$A:$A,0))*4)/23,0),"") | AN4: =IFERROR(ROUND((INDEX(Fahrerwerte!$C:$C,MATCH($A4,Fahrerwerte!$A:$A,0))*6+INDEX(Fahrerwerte!$I:$I,MATCH($A4,Fahrerwerte!$A:$A,0))*5+INDEX(Fahrerwerte!$E:$E,MATCH($A4,Fahrerwerte!$A:$A,0))*7+INDEX(Fahrerwerte!$F:$F,MATCH($A4,Fahrerwerte!$A:$A,0))*1)/19,0),"") | AO4: =IFERROR(ROUND((INDEX(Fahrerwerte!$C:$C,MATCH($A4,Fahrerwerte!$A:$A,0))*6+INDEX(Fahrerwerte!$I:$I,MATCH($A4,Fahrerwerte!$A:$A,0))*5+INDEX(Fahrerwerte!$E:$E,MATCH($A4,Fahrerwerte!$A:$A,0))*7+INDEX(Fahrerwerte!$F:$F,MATCH($A4,Fahrerwerte!$A:$A,0))*1)/19,0),"") | AP4: =IFERROR(ROUND((INDEX(Fahrerwerte!$C:$C,MATCH($A4,Fahrerwerte!$A:$A,0))*6+INDEX(Fahrerwerte!$I:$I,MATCH($A4,Fahrerwerte!$A:$A,0))*5+INDEX(Fahrerwerte!$E:$E,MATCH($A4,Fahrerwerte!$A:$A,0))*7+INDEX(Fahrerwerte!$F:$F,MATCH($A4,Fahrerwerte!$A:$A,0))*1)/19,0),"") | AQ4: =IFERROR(ROUND((INDEX(Fahrerwerte!$C:$C,MATCH($A4,Fahrerwerte!$A:$A,0))*6+INDEX(Fahrerwerte!$I:$I,MATCH($A4,Fahrerwerte!$A:$A,0))*6+INDEX(Fahrerwerte!$E:$E,MATCH($A4,Fahrerwerte!$A:$A,0))*6+INDEX(Fahrerwerte!$F:$F,MATCH($A4,Fahrerwerte!$A:$A,0))*4)/22,0),"") | AR4: =IFERROR(ROUND((INDEX(Fahrerwerte!$C:$C,MATCH($A4,Fahrerwerte!$A:$A,0))*5+INDEX(Fahrerwerte!$I:$I,MATCH($A4,Fahrerwerte!$A:$A,0))*6+INDEX(Fahrerwerte!$E:$E,MATCH($A4,Fahrerwerte!$A:$A,0))*5+INDEX(Fahrerwerte!$F:$F,MATCH($A4,Fahrerwerte!$A:$A,0))*3)/19,0),"") | AS4: =IFERROR(ROUND((INDEX(Fahrerwerte!$C:$C,MATCH($A4,Fahrerwerte!$A:$A,0))*10+INDEX(Fahrerwerte!$I:$I,MATCH($A4,Fahrerwerte!$A:$A,0))*2+INDEX(Fahrerwerte!$E:$E,MATCH($A4,Fahrerwerte!$A:$A,0))*8+INDEX(Fahrerwerte!$F:$F,MATCH($A4,Fahrerwerte!$A:$A,0))*1)/21,0),"") | AT4: =IFERROR(ROUND((INDEX(Fahrerwerte!$C:$C,MATCH($A4,Fahrerwerte!$A:$A,0))*3+INDEX(Fahrerwerte!$I:$I,MATCH($A4,Fahrerwerte!$A:$A,0))*7+INDEX(Fahrerwerte!$E:$E,MATCH($A4,Fahrerwerte!$A:$A,0))*4+INDEX(Fahrerwerte!$F:$F,MATCH($A4,Fahrerwerte!$A:$A,0))*2)/16,0),"")
A5: =IFERROR(Planung!A8,"") | B5: =IFERROR(ROUND((INDEX(Fahrerwerte!$C:$C,MATCH($A5,Fahrerwerte!$A:$A,0))*4+INDEX(Fahrerwerte!$I:$I,MATCH($A5,Fahrerwerte!$A:$A,0))*8+INDEX(Fahrerwerte!$E:$E,MATCH($A5,Fahrerwerte!$A:$A,0))*4+INDEX(Fahrerwerte!$F:$F,MATCH($A5,Fahrerwerte!$A:$A,0))*1)/17,0),"") | C5: =IFERROR(ROUND((INDEX(Fahrerwerte!$C:$C,MATCH($A5,Fahrerwerte!$A:$A,0))*5+INDEX(Fahrerwerte!$I:$I,MATCH($A5,Fahrerwerte!$A:$A,0))*6+INDEX(Fahrerwerte!$E:$E,MATCH($A5,Fahrerwerte!$A:$A,0))*5+INDEX(Fahrerwerte!$F:$F,MATCH($A5,Fahrerwerte!$A:$A,0))*2)/18,0),"") | D5: =IFERROR(ROUND((INDEX(Fahrerwerte!$C:$C,MATCH($A5,Fahrerwerte!$A:$A,0))*5+INDEX(Fahrerwerte!$I:$I,MATCH($A5,Fahrerwerte!$A:$A,0))*8+INDEX(Fahrerwerte!$E:$E,MATCH($A5,Fahrerwerte!$A:$A,0))*3+INDEX(Fahrerwerte!$F:$F,MATCH($A5,Fahrerwerte!$A:$A,0))*4)/20,0),"") | E5: =IFERROR(ROUND((INDEX(Fahrerwerte!$C:$C,MATCH($A5,Fahrerwerte!$A:$A,0))*6+INDEX(Fahrerwerte!$I:$I,MATCH($A5,Fahrerwerte!$A:$A,0))*5+INDEX(Fahrerwerte!$E:$E,MATCH($A5,Fahrerwerte!$A:$A,0))*6+INDEX(Fahrerwerte!$F:$F,MATCH($A5,Fahrerwerte!$A:$A,0))*3)/20,0),"") | F5: =IFERROR(ROUND((INDEX(Fahrerwerte!$C:$C,MATCH($A5,Fahrerwerte!$A:$A,0))*6+INDEX(Fahrerwerte!$I:$I,MATCH($A5,Fahrerwerte!$A:$A,0))*5+INDEX(Fahrerwerte!$E:$E,MATCH($A5,Fahrerwerte!$A:$A,0))*6+INDEX(Fahrerwerte!$F:$F,MATCH($A5,Fahrerwerte!$A:$A,0))*3)/20,0),"") | G5: =IFERROR(ROUND((INDEX(Fahrerwerte!$C:$C,MATCH($A5,Fahrerwerte!$A:$A,0))*5+INDEX(Fahrerwerte!$I:$I,MATCH($A5,Fahrerwerte!$A:$A,0))*6+INDEX(Fahrerwerte!$E:$E,MATCH($A5,Fahrerwerte!$A:$A,0))*5+INDEX(Fahrerwerte!$F:$F,MATCH($A5,Fahrerwerte!$A:$A,0))*1)/17,0),"") | H5: =IFERROR(ROUND((INDEX(Fahrerwerte!$C:$C,MATCH($A5,Fahrerwerte!$A:$A,0))*2+INDEX(Fahrerwerte!$I:$I,MATCH($A5,Fahrerwerte!$A:$A,0))*8+INDEX(Fahrerwerte!$E:$E,MATCH($A5,Fahrerwerte!$A:$A,0))*2+INDEX(Fahrerwerte!$F:$F,MATCH($A5,Fahrerwerte!$A:$A,0))*1)/13,0),"") | I5: =IFERROR(ROUND((INDEX(Fahrerwerte!$C:$C,MATCH($A5,Fahrerwerte!$A:$A,0))*7+INDEX(Fahrerwerte!$I:$I,MATCH($A5,Fahrerwerte!$A:$A,0))*4+INDEX(Fahrerwerte!$E:$E,MATCH($A5,Fahrerwerte!$A:$A,0))*7+INDEX(Fahrerwerte!$F:$F,MATCH($A5,Fahrerwerte!$A:$A,0))*1)/19,0),"") | J5: =IFERROR(ROUND((INDEX(Fahrerwerte!$C:$C,MATCH($A5,Fahrerwerte!$A:$A,0))*7+INDEX(Fahrerwerte!$I:$I,MATCH($A5,Fahrerwerte!$A:$A,0))*6+INDEX(Fahrerwerte!$E:$E,MATCH($A5,Fahrerwerte!$A:$A,0))*6+INDEX(Fahrerwerte!$F:$F,MATCH($A5,Fahrerwerte!$A:$A,0))*5)/24,0),"") | K5: =IFERROR(ROUND((INDEX(Fahrerwerte!$C:$C,MATCH($A5,Fahrerwerte!$A:$A,0))*7+INDEX(Fahrerwerte!$I:$I,MATCH($A5,Fahrerwerte!$A:$A,0))*6+INDEX(Fahrerwerte!$E:$E,MATCH($A5,Fahrerwerte!$A:$A,0))*6+INDEX(Fahrerwerte!$F:$F,MATCH($A5,Fahrerwerte!$A:$A,0))*5)/24,0),"") | L5: =IFERROR(ROUND((INDEX(Fahrerwerte!$C:$C,MATCH($A5,Fahrerwerte!$A:$A,0))*3+INDEX(Fahrerwerte!$I:$I,MATCH($A5,Fahrerwerte!$A:$A,0))*10+INDEX(Fahrerwerte!$E:$E,MATCH($A5,Fahrerwerte!$A:$A,0))*5+INDEX(Fahrerwerte!$F:$F,MATCH($A5,Fahrerwerte!$A:$A,0))*1)/19,0),"") | M5: =IFERROR(ROUND((INDEX(Fahrerwerte!$C:$C,MATCH($A5,Fahrerwerte!$A:$A,0))*9+INDEX(Fahrerwerte!$I:$I,MATCH($A5,Fahrerwerte!$A:$A,0))*4+INDEX(Fahrerwerte!$E:$E,MATCH($A5,Fahrerwerte!$A:$A,0))*6+INDEX(Fahrerwerte!$F:$F,MATCH($A5,Fahrerwerte!$A:$A,0))*3)/22,0),"") | N5: =IFERROR(ROUND((INDEX(Fahrerwerte!$C:$C,MATCH($A5,Fahrerwerte!$A:$A,0))*3+INDEX(Fahrerwerte!$I:$I,MATCH($A5,Fahrerwerte!$A:$A,0))*7+INDEX(Fahrerwerte!$E:$E,MATCH($A5,Fahrerwerte!$A:$A,0))*3+INDEX(Fahrerwerte!$F:$F,MATCH($A5,Fahrerwerte!$A:$A,0))*1)/14,0),"") | O5: =IFERROR(ROUND((INDEX(Fahrerwerte!$C:$C,MATCH($A5,Fahrerwerte!$A:$A,0))*7+INDEX(Fahrerwerte!$I:$I,MATCH($A5,Fahrerwerte!$A:$A,0))*5+INDEX(Fahrerwerte!$E:$E,MATCH($A5,Fahrerwerte!$A:$A,0))*7+INDEX(Fahrerwerte!$F:$F,MATCH($A5,Fahrerwerte!$A:$A,0))*1)/20,0),"") | P5: =IFERROR(ROUND((INDEX(Fahrerwerte!$C:$C,MATCH($A5,Fahrerwerte!$A:$A,0))*3+INDEX(Fahrerwerte!$I:$I,MATCH($A5,Fahrerwerte!$A:$A,0))*9+INDEX(Fahrerwerte!$E:$E,MATCH($A5,Fahrerwerte!$A:$A,0))*4+INDEX(Fahrerwerte!$F:$F,MATCH($A5,Fahrerwerte!$A:$A,0))*1)/17,0),"") | Q5: =IFERROR(ROUND((INDEX(Fahrerwerte!$C:$C,MATCH($A5,Fahrerwerte!$A:$A,0))*5+INDEX(Fahrerwerte!$I:$I,MATCH($A5,Fahrerwerte!$A:$A,0))*6+INDEX(Fahrerwerte!$E:$E,MATCH($A5,Fahrerwerte!$A:$A,0))*5+INDEX(Fahrerwerte!$F:$F,MATCH($A5,Fahrerwerte!$A:$A,0))*1)/17,0),"") | R5: =IFERROR(ROUND((INDEX(Fahrerwerte!$C:$C,MATCH($A5,Fahrerwerte!$A:$A,0))*7+INDEX(Fahrerwerte!$I:$I,MATCH($A5,Fahrerwerte!$A:$A,0))*4+INDEX(Fahrerwerte!$E:$E,MATCH($A5,Fahrerwerte!$A:$A,0))*9+INDEX(Fahrerwerte!$F:$F,MATCH($A5,Fahrerwerte!$A:$A,0))*1)/21,0),"") | S5: =IFERROR(ROUND((INDEX(Fahrerwerte!$C:$C,MATCH($A5,Fahrerwerte!$A:$A,0))*9+INDEX(Fahrerwerte!$I:$I,MATCH($A5,Fahrerwerte!$A:$A,0))*2+INDEX(Fahrerwerte!$E:$E,MATCH($A5,Fahrerwerte!$A:$A,0))*8+INDEX(Fahrerwerte!$F:$F,MATCH($A5,Fahrerwerte!$A:$A,0))*3)/22,0),"") | T5: =IFERROR(ROUND((INDEX(Fahrerwerte!$C:$C,MATCH($A5,Fahrerwerte!$A:$A,0))*3+INDEX(Fahrerwerte!$I:$I,MATCH($A5,Fahrerwerte!$A:$A,0))*6+INDEX(Fahrerwerte!$E:$E,MATCH($A5,Fahrerwerte!$A:$A,0))*2+INDEX(Fahrerwerte!$F:$F,MATCH($A5,Fahrerwerte!$A:$A,0))*1)/12,0),"") | U5: =IFERROR(ROUND((INDEX(Fahrerwerte!$C:$C,MATCH($A5,Fahrerwerte!$A:$A,0))*8+INDEX(Fahrerwerte!$I:$I,MATCH($A5,Fahrerwerte!$A:$A,0))*3+INDEX(Fahrerwerte!$E:$E,MATCH($A5,Fahrerwerte!$A:$A,0))*9+INDEX(Fahrerwerte!$F:$F,MATCH($A5,Fahrerwerte!$A:$A,0))*1)/21,0),"") | V5: =IFERROR(ROUND((INDEX(Fahrerwerte!$C:$C,MATCH($A5,Fahrerwerte!$A:$A,0))*8+INDEX(Fahrerwerte!$I:$I,MATCH($A5,Fahrerwerte!$A:$A,0))*3+INDEX(Fahrerwerte!$E:$E,MATCH($A5,Fahrerwerte!$A:$A,0))*6+INDEX(Fahrerwerte!$F:$F,MATCH($A5,Fahrerwerte!$A:$A,0))*2)/19,0),"") | W5: =IFERROR(ROUND((INDEX(Fahrerwerte!$C:$C,MATCH($A5,Fahrerwerte!$A:$A,0))*9+INDEX(Fahrerwerte!$I:$I,MATCH($A5,Fahrerwerte!$A:$A,0))*2+INDEX(Fahrerwerte!$E:$E,MATCH($A5,Fahrerwerte!$A:$A,0))*9+INDEX(Fahrerwerte!$F:$F,MATCH($A5,Fahrerwerte!$A:$A,0))*1)/21,0),"") | X5: =IFERROR(ROUND((INDEX(Fahrerwerte!$C:$C,MATCH($A5,Fahrerwerte!$A:$A,0))*9+INDEX(Fahrerwerte!$I:$I,MATCH($A5,Fahrerwerte!$A:$A,0))*2+INDEX(Fahrerwerte!$E:$E,MATCH($A5,Fahrerwerte!$A:$A,0))*9+INDEX(Fahrerwerte!$F:$F,MATCH($A5,Fahrerwerte!$A:$A,0))*1)/21,0),"") | Y5: =IFERROR(ROUND((INDEX(Fahrerwerte!$C:$C,MATCH($A5,Fahrerwerte!$A:$A,0))*7+INDEX(Fahrerwerte!$I:$I,MATCH($A5,Fahrerwerte!$A:$A,0))*4+INDEX(Fahrerwerte!$E:$E,MATCH($A5,Fahrerwerte!$A:$A,0))*7+INDEX(Fahrerwerte!$F:$F,MATCH($A5,Fahrerwerte!$A:$A,0))*4)/22,0),"") | Z5: =IFERROR(ROUND((INDEX(Fahrerwerte!$C:$C,MATCH($A5,Fahrerwerte!$A:$A,0))*6+INDEX(Fahrerwerte!$I:$I,MATCH($A5,Fahrerwerte!$A:$A,0))*6+INDEX(Fahrerwerte!$E:$E,MATCH($A5,Fahrerwerte!$A:$A,0))*6+INDEX(Fahrerwerte!$F:$F,MATCH($A5,Fahrerwerte!$A:$A,0))*1)/19,0),"") | AA5: =IFERROR(ROUND((INDEX(Fahrerwerte!$C:$C,MATCH($A5,Fahrerwerte!$A:$A,0))*10+INDEX(Fahrerwerte!$I:$I,MATCH($A5,Fahrerwerte!$A:$A,0))*3+INDEX(Fahrerwerte!$E:$E,MATCH($A5,Fahrerwerte!$A:$A,0))*6+INDEX(Fahrerwerte!$F:$F,MATCH($A5,Fahrerwerte!$A:$A,0))*5)/24,0),"") | AB5: =IFERROR(ROUND((INDEX(Fahrerwerte!$C:$C,MATCH($A5,Fahrerwerte!$A:$A,0))*8+INDEX(Fahrerwerte!$I:$I,MATCH($A5,Fahrerwerte!$A:$A,0))*3+INDEX(Fahrerwerte!$E:$E,MATCH($A5,Fahrerwerte!$A:$A,0))*7+INDEX(Fahrerwerte!$F:$F,MATCH($A5,Fahrerwerte!$A:$A,0))*3)/21,0),"") | AC5: =IFERROR(ROUND((INDEX(Fahrerwerte!$C:$C,MATCH($A5,Fahrerwerte!$A:$A,0))*7+INDEX(Fahrerwerte!$I:$I,MATCH($A5,Fahrerwerte!$A:$A,0))*3+INDEX(Fahrerwerte!$E:$E,MATCH($A5,Fahrerwerte!$A:$A,0))*7+INDEX(Fahrerwerte!$F:$F,MATCH($A5,Fahrerwerte!$A:$A,0))*2)/19,0),"") | AD5: =IFERROR(ROUND((INDEX(Fahrerwerte!$C:$C,MATCH($A5,Fahrerwerte!$A:$A,0))*9+INDEX(Fahrerwerte!$I:$I,MATCH($A5,Fahrerwerte!$A:$A,0))*4+INDEX(Fahrerwerte!$E:$E,MATCH($A5,Fahrerwerte!$A:$A,0))*6+INDEX(Fahrerwerte!$F:$F,MATCH($A5,Fahrerwerte!$A:$A,0))*5)/24,0),"") | AE5: =IFERROR(ROUND((INDEX(Fahrerwerte!$C:$C,MATCH($A5,Fahrerwerte!$A:$A,0))*5+INDEX(Fahrerwerte!$I:$I,MATCH($A5,Fahrerwerte!$A:$A,0))*6+INDEX(Fahrerwerte!$E:$E,MATCH($A5,Fahrerwerte!$A:$A,0))*5+INDEX(Fahrerwerte!$F:$F,MATCH($A5,Fahrerwerte!$A:$A,0))*3)/19,0),"") | AF5: =IFERROR(ROUND((INDEX(Fahrerwerte!$C:$C,MATCH($A5,Fahrerwerte!$A:$A,0))*10+INDEX(Fahrerwerte!$I:$I,MATCH($A5,Fahrerwerte!$A:$A,0))*4+INDEX(Fahrerwerte!$E:$E,MATCH($A5,Fahrerwerte!$A:$A,0))*7+INDEX(Fahrerwerte!$F:$F,MATCH($A5,Fahrerwerte!$A:$A,0))*6)/27,0),"") | AG5: =IFERROR(ROUND((INDEX(Fahrerwerte!$C:$C,MATCH($A5,Fahrerwerte!$A:$A,0))*8+INDEX(Fahrerwerte!$I:$I,MATCH($A5,Fahrerwerte!$A:$A,0))*3+INDEX(Fahrerwerte!$E:$E,MATCH($A5,Fahrerwerte!$A:$A,0))*8+INDEX(Fahrerwerte!$F:$F,MATCH($A5,Fahrerwerte!$A:$A,0))*1)/20,0),"") | AH5: =IFERROR(ROUND((INDEX(Fahrerwerte!$C:$C,MATCH($A5,Fahrerwerte!$A:$A,0))*6+INDEX(Fahrerwerte!$I:$I,MATCH($A5,Fahrerwerte!$A:$A,0))*5+INDEX(Fahrerwerte!$E:$E,MATCH($A5,Fahrerwerte!$A:$A,0))*6+INDEX(Fahrerwerte!$F:$F,MATCH($A5,Fahrerwerte!$A:$A,0))*3)/20,0),"") | AI5: =IFERROR(ROUND((INDEX(Fahrerwerte!$C:$C,MATCH($A5,Fahrerwerte!$A:$A,0))*3+INDEX(Fahrerwerte!$I:$I,MATCH($A5,Fahrerwerte!$A:$A,0))*8+INDEX(Fahrerwerte!$E:$E,MATCH($A5,Fahrerwerte!$A:$A,0))*5+INDEX(Fahrerwerte!$F:$F,MATCH($A5,Fahrerwerte!$A:$A,0))*2)/18,0),"") | AJ5: =IFERROR(ROUND((INDEX(Fahrerwerte!$C:$C,MATCH($A5,Fahrerwerte!$A:$A,0))*2+INDEX(Fahrerwerte!$I:$I,MATCH($A5,Fahrerwerte!$A:$A,0))*9+INDEX(Fahrerwerte!$E:$E,MATCH($A5,Fahrerwerte!$A:$A,0))*2+INDEX(Fahrerwerte!$F:$F,MATCH($A5,Fahrerwerte!$A:$A,0))*1)/14,0),"") | AK5: =IFERROR(ROUND((INDEX(Fahrerwerte!$C:$C,MATCH($A5,Fahrerwerte!$A:$A,0))*6+INDEX(Fahrerwerte!$I:$I,MATCH($A5,Fahrerwerte!$A:$A,0))*6+INDEX(Fahrerwerte!$E:$E,MATCH($A5,Fahrerwerte!$A:$A,0))*6+INDEX(Fahrerwerte!$F:$F,MATCH($A5,Fahrerwerte!$A:$A,0))*3)/21,0),"") | AL5: =IFERROR(ROUND((INDEX(Fahrerwerte!$C:$C,MATCH($A5,Fahrerwerte!$A:$A,0))*5+INDEX(Fahrerwerte!$I:$I,MATCH($A5,Fahrerwerte!$A:$A,0))*6+INDEX(Fahrerwerte!$E:$E,MATCH($A5,Fahrerwerte!$A:$A,0))*5+INDEX(Fahrerwerte!$F:$F,MATCH($A5,Fahrerwerte!$A:$A,0))*2)/18,0),"") | AM5: =IFERROR(ROUND((INDEX(Fahrerwerte!$C:$C,MATCH($A5,Fahrerwerte!$A:$A,0))*9+INDEX(Fahrerwerte!$I:$I,MATCH($A5,Fahrerwerte!$A:$A,0))*3+INDEX(Fahrerwerte!$E:$E,MATCH($A5,Fahrerwerte!$A:$A,0))*7+INDEX(Fahrerwerte!$F:$F,MATCH($A5,Fahrerwerte!$A:$A,0))*4)/23,0),"") | AN5: =IFERROR(ROUND((INDEX(Fahrerwerte!$C:$C,MATCH($A5,Fahrerwerte!$A:$A,0))*6+INDEX(Fahrerwerte!$I:$I,MATCH($A5,Fahrerwerte!$A:$A,0))*5+INDEX(Fahrerwerte!$E:$E,MATCH($A5,Fahrerwerte!$A:$A,0))*7+INDEX(Fahrerwerte!$F:$F,MATCH($A5,Fahrerwerte!$A:$A,0))*1)/19,0),"") | AO5: =IFERROR(ROUND((INDEX(Fahrerwerte!$C:$C,MATCH($A5,Fahrerwerte!$A:$A,0))*6+INDEX(Fahrerwerte!$I:$I,MATCH($A5,Fahrerwerte!$A:$A,0))*5+INDEX(Fahrerwerte!$E:$E,MATCH($A5,Fahrerwerte!$A:$A,0))*7+INDEX(Fahrerwerte!$F:$F,MATCH($A5,Fahrerwerte!$A:$A,0))*1)/19,0),"") | AP5: =IFERROR(ROUND((INDEX(Fahrerwerte!$C:$C,MATCH($A5,Fahrerwerte!$A:$A,0))*6+INDEX(Fahrerwerte!$I:$I,MATCH($A5,Fahrerwerte!$A:$A,0))*5+INDEX(Fahrerwerte!$E:$E,MATCH($A5,Fahrerwerte!$A:$A,0))*7+INDEX(Fahrerwerte!$F:$F,MATCH($A5,Fahrerwerte!$A:$A,0))*1)/19,0),"") | AQ5: =IFERROR(ROUND((INDEX(Fahrerwerte!$C:$C,MATCH($A5,Fahrerwerte!$A:$A,0))*6+INDEX(Fahrerwerte!$I:$I,MATCH($A5,Fahrerwerte!$A:$A,0))*6+INDEX(Fahrerwerte!$E:$E,MATCH($A5,Fahrerwerte!$A:$A,0))*6+INDEX(Fahrerwerte!$F:$F,MATCH($A5,Fahrerwerte!$A:$A,0))*4)/22,0),"") | AR5: =IFERROR(ROUND((INDEX(Fahrerwerte!$C:$C,MATCH($A5,Fahrerwerte!$A:$A,0))*5+INDEX(Fahrerwerte!$I:$I,MATCH($A5,Fahrerwerte!$A:$A,0))*6+INDEX(Fahrerwerte!$E:$E,MATCH($A5,Fahrerwerte!$A:$A,0))*5+INDEX(Fahrerwerte!$F:$F,MATCH($A5,Fahrerwerte!$A:$A,0))*3)/19,0),"") | AS5: =IFERROR(ROUND((INDEX(Fahrerwerte!$C:$C,MATCH($A5,Fahrerwerte!$A:$A,0))*10+INDEX(Fahrerwerte!$I:$I,MATCH($A5,Fahrerwerte!$A:$A,0))*2+INDEX(Fahrerwerte!$E:$E,MATCH($A5,Fahrerwerte!$A:$A,0))*8+INDEX(Fahrerwerte!$F:$F,MATCH($A5,Fahrerwerte!$A:$A,0))*1)/21,0),"") | AT5: =IFERROR(ROUND((INDEX(Fahrerwerte!$C:$C,MATCH($A5,Fahrerwerte!$A:$A,0))*3+INDEX(Fahrerwerte!$I:$I,MATCH($A5,Fahrerwerte!$A:$A,0))*7+INDEX(Fahrerwerte!$E:$E,MATCH($A5,Fahrerwerte!$A:$A,0))*4+INDEX(Fahrerwerte!$F:$F,MATCH($A5,Fahrerwerte!$A:$A,0))*2)/16,0),"")
